Workbook

Sheet Notes
B1: Notes in Using the Table
B2: 1 | C2: The final grade is calculated from three components—Class Standing, Project, and Examination—which sum to a total of 100%.
B3: 2 | C3: The specific weights within Class Standing and the Project are adjustable, but Attendance is fixed at 5% of the final grade.
B4: 3 | C4: A mark of 'A' will be the official entry on the grade sheet for any requirement that was not submitted. This mark corresponds to a numerical score of zero during grade computation. (Optional)
B5: 4 | C5: For Freezing Panes, put click cell D14, Freeze Panes, Freeze Panes
B6: 5 | C6: For further assistance, ask the ADMIN.
C8: Grading 1
C9: Exam | F9: 0.5
C10: Class Standing | F10: 0.35
D11: Attendance | E11: 0.05
D12: Activity
D13: Quizzes
C14: Project | F14: 0.15
D15: Notebook
D16: Plates
F17: =SUM(F9:F15) -> 1
C19: Grading 2
C20: Exam | F20: 0.575
C21: Class Standing | F21: 0.425
D22: Attendance | E22: 0.05
D23: Activity
D24: Quizzes
C25: Project | F25: 0
D26: Notebook
D27: Plates
F28: =SUM(F20:F27) -> 1

Sheet Transmutation Table
A1: raw | B1: transmuted | C1: PR grade
A2: 0 | B2: 70 | C2: 5 | D2: Poor
A3: 10 | B3: 71 | C3: 5 | D3: Poor
A4: 20 | B4: 72 | C4: 5 | D4: Poor
A5: 30 | B5: 73 | C5: 5 | D5: Poor
A6: 40 | B6: 74 | C6: 5 | D6: Poor
A7: 50 | B7: 75 | C7: 3 | D7: Fair
A8: 52 | B8: 76 | C8: 2.9 | D8: Fair
A9: 54 | B9: 77 | C9: 2.8 | D9: Fair
A10: 56 | B10: 78 | C10: 2.75 | D10: Fair
A11: 58 | B11: 79 | C11: 2.7 | D11: Fair
A12: 60 | B12: 80 | C12: 2.6 | D12: Good
A13: 62 | B13: 81 | C13: 2.5 | D13: Good
... A32: 100 | B32: 100 | C32: 1 | D32: Excellent

Sheet with project
A1: Naga College Foundation, Inc
A2: COLLEGE OF ENGINEERING
A4: FINAL REPORT OF GRADES
A5: 1st Semester, School Year 2025 - 2026
A7: Subj. Code / Title: | BQ7: Course/Section:
A8: Instructor: | C8: ENGR. JOHN KIRK Y. NAVARRETE | Q8: Credit Unit: | AV8: Time: | BR8: Days:
A10: No. | B10: Name | D10: =_xlfn.CONCAT("Per. Exam ","(",SUM(G12)*100,"%",")") -> Per. Exam (50%) | H10: =_xlfn.CONCAT("Class Standing ","(",SUM(S13,AF13,AS13)*100,"%",")") -> Class Standing (35%) | AW10: =_xlfn.CONCAT("Project ","(",SUM(BA13,BN13)*100,"%",")") -> Project (15%) | BR10: Ave. Grade | BS10: Finals Grade | BT10: Remarks | BV10: =SUM(BQ11,AS13,AF13,S13,G12) -> 1
O11: =_xlfn.CONCAT("Attendance ","(",SUM(S13)*100,"%",")") -> Attendance (5%) | T11: =_xlfn.CONCAT("Seatwork/Homework/Activity ","(",SUM(W13,AA13,AE13)*100,"%",")") -> Seatwork/Homework/Activity (10%) | AG11: =_xlfn.CONCAT("Quizzes ","(",SUM(AJ13,AN13,AR13)*100,"%",")") -> Quizzes (20%) | AT11: Ave Q/A | AU11: Grade | AV11: WG CS | AW11: =_xlfn.CONCAT("Notebook ","(",SUM(BA13)*100,"%",")") -> Notebook (5%) | BB11: =_xlfn.CONCAT("Plates ","(",SUM(BE13,BI13,BM13)*100,"%",")") -> Plates (10%) | BO11: Project | BP11: Grade | BQ11: =SUM(BA13,BN13) -> 0.15 | BV11: Hide these Rows
D12: ITEMS | F12: 10 | G12: 0.5 | O12: RAW | P12: TOTAL | Q12: 1.5 | R12: Grade | S12: WS | T12: SW4.1 | X12: SW4.2 | AB12: SW4.3 | AF12: WS | AG12: Q4.1 | AK12: Q4.2 | AO12: Q4.3 | AS12: WS | AW12: C1 | AX12: C2 | AY12: TOTAL | BA12: WS | BB12: PLATE1.1 | BF12: PLATE1.2 | BJ12: PLATE1.3 | BN12: WS
D13: Score | F13: Grade | G13: WG PE | P13: 2.5 | Q13: Abs. | S13: 0.05 | T13: 10 | U13: % | V13: EQV | W13: =AF13/3 -> 0.033333333 | X13: 10 | Y13: % | Z13: EQV | AA13: =W13 -> 0.033333333 | AB13: 50 | AC13: % | AD13: EQV | AE13: =AA13 -> 0.033333333 | AF13: 0.1 | AG13: 15 | AH13: % | AI13: EQV | AJ13: =AS13/3 -> 0.066666667 | AK13: 15 | AL13: % | AM13: EQV | AN13: =AJ13 -> 0.066666667 | AO13: 50 | AP13: % | AQ13: EQV | AR13: =AN13 -> 0.066666667 | AS13: 0.2 | AW13: 100 | AY13: =SUM(AW13:AX13) -> 100 | AZ13: EQV | BA13: 0.05 | BB13: 50 | BC13: % | BD13: EQV | BE13: =BN13/3 -> 0.033333333 | BF13: 50 | BG13: % | BH13: EQV | BI13: =BE13 -> 0.033333333 | BJ13: 50 | BK13: % | BL13: EQV | BM13: =BI13 -> 0.033333333 | BN13: 0.1 | BQ13: WG Proj.
A14: 1 | B14: Student 1 | E14: =_xlfn.CONCAT("/","",$F$12,"","") -> /10 | F14: =IFERROR(VLOOKUP((D14/$F$12)*100,'Transmutation Table'!$A$2:$B$32,2),0) -> 70 | G14: =$G$12*F14 -> 35 | O14: =COUNTIF(H14:N14,"P")+COUNTIF(H14:N14,"E")+COUNTIF(H14:N14,"L")*(1/3) -> 0 | P14: =COUNTA(H14:N14) -> 0 | Q14: =(P14-O14)*$Q$12 -> 0 | R14: =100-(Q14*$P$13) -> 100 | S14: =R14*$S$13 -> 5 | U14: =IFERROR(T14/$T$13*100,0) -> 0 | V14: =IF(T14="A",0,VLOOKUP(U14,'Transmutation Table'!$A$2:$B$32,2)) -> 70 | W14: =V14*$W$13 -> 2.3333333 | Y14: =IFERROR(X14/$X$13*100,0) -> 0 | Z14: =IF(X14="A",0,VLOOKUP(Y14,'Transmutation Table'!$A$2:$B$32,2)) -> 70 | AA14: =Z14*$AA$13 -> 2.3333333 | AC14: =IFERROR(AB14/$AB$13*100,0) -> 0 | AD14: =IF(AB14="A",0,VLOOKUP(AC14,'Transmutation Table'!$A$2:$B$32,2)) -> 70 | AE14: =AD14*$AE$13 -> 2.3333333 | AF14: =SUM(W14,AA14,AE14) -> 7 | AH14: =IFERROR(AG14/$AG$13*100,0) -> 0 | AI14: =IF(AG14="A",0,VLOOKUP(AH14,'Transmutation Table'!$A$2:$B$32,2)) -> 70 | AJ14: =AI14*$AJ$13 -> 4.6666667 | AL14: =IFERROR(AK14/$AK$13*100,0) -> 0 | AM14: =IF(AK14="A",0,VLOOKUP(AL14,'Transmutation Table'!$A$2:$B$32,2)) -> 70 | AN14: =AM14*$AN$13 -> 4.6666667 | AP14: =IFERROR(AO14/$AO$13*100,0) -> 0 | AQ14: =IF(AO14="A",0,VLOOKUP(AP14,'Transmutation Table'!$A$2:$B$32,2)) -> 70 | AR14: =AQ14*$AR$13 -> 4.6666667 | AS14: =SUM(AJ14,AN14,AR14) -> 14 | AT14: =AVERAGE(AH14,AL14,AP14) -> 0 | AU14: =AVERAGE(AI14,AM14,AQ14) -> 70 | AV14: =SUM(S14,AF14,AS14) -> 26 | AY14: =SUM(AW14:AX14) -> 0 | AZ14: =50+(AY14/$AY$13)*50 -> 50 | BA14: =AZ14*$BA$13 -> 2.5 | BC14: =IFERROR(BB14/$T$13*100,0) -> 0 | BD14: =IF(BB14="A",0,VLOOKUP(BC14,'Transmutation Table'!$A$2:$B$32,2)) -> 70 | BE14: =BD14*$BE$13 -> 2.3333333 | BG14: =IFERROR(BF14/$X$13*100,0) -> 0 | BH14: =IF(BF14="A",0,VLOOKUP(BG14,'Transmutation Table'!$A$2:$B$32,2)) -> 70 | BI14: =BH14*$BI$13 -> 2.3333333 | BK14: =IFERROR(BJ14/#REF!*100,0) -> 0 | BL14: =IF(BJ14="A",0,VLOOKUP(BK14,'Transmutation Table'!$A$2:$B$32,2)) -> 70 | BM14: =BL14*$BM$13 -> 2.3333333 | BN14: =SUM(BE14,BI14,BM14) -> 7 | BO14: =AVERAGE(AY14) -> 0 | BP14: =AZ14 -> 50 | BQ14: =SUM(BA14,BN14) -> 9.5 | BR14: =SUM(G14,AV14,BQ14) -> 70.5 | BS14: =IFERROR(VLOOKUP(BR14,'Transmutation Table'!$B$2:$V$32,2),5) -> 5 | BT14: =IF(BR14>=75,"PASSED","FAILED") -> FAILED | BV14: Permit
A15: 2 | B15: Student 2 | E15: =_xlfn.CONCAT("/","",$F$12,"","") -> /10 | F15: =IFERROR(VLOOKUP((D15/$F$12)*100,'Transmutation Table'!$A$2:$B$32,2),0) -> 70 | G15: =$G$12*F15 -> 35 | O15: =COUNTIF(H15:N15,"P")+COUNTIF(H15:N15,"E")+COUNTIF(H15:N15,"L")*(1/3) -> 0 | P15: =COUNTA(H15:N15) -> 0 | Q15: =(P15-O15)*$Q$12 -> 0 | R15: =100-(Q15*$P$13) -> 100 | S15: =R15*$S$13 -> 5 | U15: =IFERROR(T15/$T$13*100,0) -> 0 | V15: =IF(T15="A",0,VLOOKUP(U15,'Transmutation Table'!$A$2:$B$32,2)) -> 70 | W15: =V15*$W$13 -> 2.3333333 | Y15: =IFERROR(X15/$X$13*100,0) -> 0 | Z15: =IF(X15="A",0,VLOOKUP(Y15,'Transmutation Table'!$A$2:$B$32,2)) -> 70 | AA15: =Z15*$AA$13 -> 2.3333333 | AC15: =IFERROR(AB15/$AB$13*100,0) -> 0 | AD15: =IF(AB15="A",0,VLOOKUP(AC15,'Transmutation Table'!$A$2:$B$32,2)) -> 70 | AE15: =AD15*$AE$13 -> 2.3333333 | AF15: =SUM(W15,AA15,AE15) -> 7 | AH15: =IFERROR(AG15/$AG$13*100,0) -> 0 | AI15: =IF(AG15="A",0,VLOOKUP(AH15,'Transmutation Table'!$A$2:$B$32,2)) -> 70 | AJ15: =AI15*$AJ$13 -> 4.6666667 | AL15: =IFERROR(AK15/$AK$13*100,0) -> 0 | AM15: =IF(AK15="A",0,VLOOKUP(AL15,'Transmutation Table'!$A$2:$B$32,2)) -> 70 | AN15: =AM15*$AN$13 -> 4.6666667 | AP15: =IFERROR(AO15/$AO$13*100,0) -> 0 | AQ15: =IF(AO15="A",0,VLOOKUP(AP15,'Transmutation Table'!$A$2:$B$32,2)) -> 70 | AR15: =AQ15*$AR$13 -> 4.6666667 | AS15: =SUM(AJ15,AN15,AR15) -> 14 | AT15: =AVERAGE(AH15,AL15,AP15) -> 0 | AU15: =AVERAGE(AI15,AM15,AQ15) -> 70 | AV15: =SUM(S15,AF15,AS15) -> 26 | AY15: =SUM(AW15:AX15) -> 0 | AZ15: =50+(AY15/$AY$13)*50 -> 50 | BA15: =AZ15*$BA$13 -> 2.5 | BC15: =IFERROR(BB15/$T$13*100,0) -> 0 | BD15: =IF(BB15="A",0,VLOOKUP(BC15,'Transmutation Table'!$A$2:$B$32,2)) -> 70 | BE15: =BD15*$BE$13 -> 2.3333333 | BG15: =IFERROR(BF15/$X$13*100,0) -> 0 | BH15: =IF(BF15="A",0,VLOOKUP(BG15,'Transmutation Table'!$A$2:$B$32,2)) -> 70 | BI15: =BH15*$BI$13 -> 2.3333333 | BK15: =IFERROR(BJ15/#REF!*100,0) -> 0 | BL15: =IF(BJ15="A",0,VLOOKUP(BK15,'Transmutation Table'!$A$2:$B$32,2)) -> 70 | BM15: =BL15*$BM$13 -> 2.3333333 | BN15: =SUM(BE15,BI15,BM15) -> 7 | BO15: =AVERAGE(AY15) -> 0 | BP15: =AZ15 -> 50 | BQ15: =SUM(BA15,BN15) -> 9.5 | BR15: =SUM(G15,AV15,BQ15) -> 70.5 | BS15: =IFERROR(VLOOKUP(BR15,'Transmutation Table'!$B$2:$V$32,2),5) -> 5 | BT15: =IF(BR15>=75,"PASSED","FAILED") -> FAILED | BV15: Permit
A16: 3 | B16: Student 3 | E16: =_xlfn.CONCAT("/","",$F$12,"","") -> /10 | F16: =IFERROR(VLOOKUP((D16/$F$12)*100,'Transmutation Table'!$A$2:$B$32,2),0) -> 70 | G16: =$G$12*F16 -> 35 | O16: =COUNTIF(H16:N16,"P")+COUNTIF(H16:N16,"E")+COUNTIF(H16:N16,"L")*(1/3) -> 0 | P16: =COUNTA(H16:N16) -> 0 | Q16: =(P16-O16)*$Q$12 -> 0 | R16: =100-(Q16*$P$13) -> 100 | S16: =R16*$S$13 -> 5 | U16: =IFERROR(T16/$T$13*100,0) -> 0 | V16: =IF(T16="A",0,VLOOKUP(U16,'Transmutation Table'!$A$2:$B$32,2)) -> 70 | W16: =V16*$W$13 -> 2.3333333 | Y16: =IFERROR(X16/$X$13*100,0) -> 0 | Z16: =IF(X16="A",0,VLOOKUP(Y16,'Transmutation Table'!$A$2:$B$32,2)) -> 70 | AA16: =Z16*$AA$13 -> 2.3333333 | AC16: =IFERROR(AB16/$AB$13*100,0) -> 0 | AD16: =IF(AB16="A",0,VLOOKUP(AC16,'Transmutation Table'!$A$2:$B$32,2)) -> 70 | AE16: =AD16*$AE$13 -> 2.3333333 | AF16: =SUM(W16,AA16,AE16) -> 7 | AH16: =IFERROR(AG16/$AG$13*100,0) -> 0 | AI16: =IF(AG16="A",0,VLOOKUP(AH16,'Transmutation Table'!$A$2:$B$32,2)) -> 70 | AJ16: =AI16*$AJ$13 -> 4.6666667 | AL16: =IFERROR(AK16/$AK$13*100,0) -> 0 | AM16: =IF(AK16="A",0,VLOOKUP(AL16,'Transmutation Table'!$A$2:$B$32,2)) -> 70 | AN16: =AM16*$AN$13 -> 4.6666667 | AP16: =IFERROR(AO16/$AO$13*100,0) -> 0 | AQ16: =IF(AO16="A",0,VLOOKUP(AP16,'Transmutation Table'!$A$2:$B$32,2)) -> 70 | AR16: =AQ16*$AR$13 -> 4.6666667 | AS16: =SUM(AJ16,AN16,AR16) -> 14 | AT16: =AVERAGE(AH16,AL16,AP16) -> 0 | AU16: =AVERAGE(AI16,AM16,AQ16) -> 70 | AV16: =SUM(S16,AF16,AS16) -> 26 | AY16: =SUM(AW16:AX16) -> 0 | AZ16: =50+(AY16/$AY$13)*50 -> 50 | BA16: =AZ16*$BA$13 -> 2.5 | BC16: =IFERROR(BB16/$T$13*100,0) -> 0 | BD16: =IF(BB16="A",0,VLOOKUP(BC16,'Transmutation Table'!$A$2:$B$32,2)) -> 70 | BE16: =BD16*$BE$13 -> 2.3333333 | BG16: =IFERROR(BF16/$X$13*100,0) -> 0 | BH16: =IF(BF16="A",0,VLOOKUP(BG16,'Transmutation Table'!$A$2:$B$32,2)) -> 70 | BI16: =BH16*$BI$13 -> 2.3333333 | BK16: =IFERROR(BJ16/#REF!*100,0) -> 0 | BL16: =IF(BJ16="A",0,VLOOKUP(BK16,'Transmutation Table'!$A$2:$B$32,2)) -> 70 | BM16: =BL16*$BM$13 -> 2.3333333 | BN16: =SUM(BE16,BI16,BM16) -> 7 | BO16: =AVERAGE(AY16) -> 0 | BP16: =AZ16 -> 50 | BQ16: =SUM(BA16,BN16) -> 9.5 | BR16: =SUM(G16,AV16,BQ16) -> 70.5 | BS16: =IFERROR(VLOOKUP(BR16,'Transmutation Table'!$B$2:$V$32,2),5) -> 5 | BT16: =IF(BR16>=75,"PASSED","FAILED") -> FAILED
A17: 4 | B17: Student 4 | E17: =_xlfn.CONCAT("/","",$F$12,"","") -> /10 | F17: =IFERROR(VLOOKUP((D17/$F$12)*100,'Transmutation Table'!$A$2:$B$32,2),0) -> 70 | G17: =$G$12*F17 -> 35 | O17: =COUNTIF(H17:N17,"P")+COUNTIF(H17:N17,"E")+COUNTIF(H17:N17,"L")*(1/3) -> 0 | P17: =COUNTA(H17:N17) -> 0 | Q17: =(P17-O17)*$Q$12 -> 0 | R17: =100-(Q17*$P$13) -> 100 | S17: =R17*$S$13 -> 5 | U17: =IFERROR(T17/$T$13*100,0) -> 0 | V17: =IF(T17="A",0,VLOOKUP(U17,'Transmutation Table'!$A$2:$B$32,2)) -> 70 | W17: =V17*$W$13 -> 2.3333333 | Y17: =IFERROR(X17/$X$13*100,0) -> 0 | Z17: =IF(X17="A",0,VLOOKUP(Y17,'Transmutation Table'!$A$2:$B$32,2)) -> 70 | AA17: =Z17*$AA$13 -> 2.3333333 | AC17: =IFERROR(AB17/$AB$13*100,0) -> 0 | AD17: =IF(AB17="A",0,VLOOKUP(AC17,'Transmutation Table'!$A$2:$B$32,2)) -> 70 | AE17: =AD17*$AE$13 -> 2.3333333 | AF17: =SUM(W17,AA17,AE17) -> 7 | AH17: =IFERROR(AG17/$AG$13*100,0) -> 0 | AI17: =IF(AG17="A",0,VLOOKUP(AH17,'Transmutation Table'!$A$2:$B$32,2)) -> 70 | AJ17: =AI17*$AJ$13 -> 4.6666667 | AL17: =IFERROR(AK17/$AK$13*100,0) -> 0 | AM17: =IF(AK17="A",0,VLOOKUP(AL17,'Transmutation Table'!$A$2:$B$32,2)) -> 70 | AN17: =AM17*$AN$13 -> 4.6666667 | AP17: =IFERROR(AO17/$AO$13*100,0) -> 0 | AQ17: =IF(AO17="A",0,VLOOKUP(AP17,'Transmutation Table'!$A$2:$B$32,2)) -> 70 | AR17: =AQ17*$AR$13 -> 4.6666667 | AS17: =SUM(AJ17,AN17,AR17) -> 14 | AT17: =AVERAGE(AH17,AL17,AP17) -> 0 | AU17: =AVERAGE(AI17,AM17,AQ17) -> 70 | AV17: =SUM(S17,AF17,AS17) -> 26 | AY17: =SUM(AW17:AX17) -> 0 | AZ17: =50+(AY17/$AY$13)*50 -> 50 | BA17: =AZ17*$BA$13 -> 2.5 | BC17: =IFERROR(BB17/$T$13*100,0) -> 0 | BD17: =IF(BB17="A",0,VLOOKUP(BC17,'Transmutation Table'!$A$2:$B$32,2)) -> 70 | BE17: =BD17*$BE$13 -> 2.3333333 | BG17: =IFERROR(BF17/$X$13*100,0) -> 0 | BH17: =IF(BF17="A",0,VLOOKUP(BG17,'Transmutation Table'!$A$2:$B$32,2)) -> 70 | BI17: =BH17*$BI$13 -> 2.3333333 | BK17: =IFERROR(BJ17/#REF!*100,0) -> 0 | BL17: =IF(BJ17="A",0,VLOOKUP(BK17,'Transmutation Table'!$A$2:$B$32,2)) -> 70 | BM17: =BL17*$BM$13 -> 2.3333333 | BN17: =SUM(BE17,BI17,BM17) -> 7 | BO17: =AVERAGE(AY17) -> 0 | BP17: =AZ17 -> 50 | BQ17: =SUM(BA17,BN17) -> 9.5 | BR17: =SUM(G17,AV17,BQ17) -> 70.5 | BS17: =IFERROR(VLOOKUP(BR17,'Transmutation Table'!$B$2:$V$32,2),5) -> 5 | BT17: =IF(BR17>=75,"PASSED","FAILED") -> FAILED | BV17: Permit
A18: 5 | B18: Student 5 | E18: =_xlfn.CONCAT("/","",$F$12,"","") -> /10 | F18: =IFERROR(VLOOKUP((D18/$F$12)*100,'Transmutation Table'!$A$2:$B$32,2),0) -> 70 | G18: =$G$12*F18 -> 35 | O18: =COUNTIF(H18:N18,"P")+COUNTIF(H18:N18,"E")+COUNTIF(H18:N18,"L")*(1/3) -> 0 | P18: =COUNTA(H18:N18) -> 0 | Q18: =(P18-O18)*$Q$12 -> 0 | R18: =100-(Q18*$P$13) -> 100 | S18: =R18*$S$13 -> 5 | U18: =IFERROR(T18/$T$13*100,0) -> 0 | V18: =IF(T18="A",0,VLOOKUP(U18,'Transmutation Table'!$A$2:$B$32,2)) -> 70 | W18: =V18*$W$13 -> 2.3333333 | Y18: =IFERROR(X18/$X$13*100,0) -> 0 | Z18: =IF(X18="A",0,VLOOKUP(Y18,'Transmutation Table'!$A$2:$B$32,2)) -> 70 | AA18: =Z18*$AA$13 -> 2.3333333 | AC18: =IFERROR(AB18/$AB$13*100,0) -> 0 | AD18: =IF(AB18="A",0,VLOOKUP(AC18,'Transmutation Table'!$A$2:$B$32,2)) -> 70 | AE18: =AD18*$AE$13 -> 2.3333333 | AF18: =SUM(W18,AA18,AE18) -> 7 | AH18: =IFERROR(AG18/$AG$13*100,0) -> 0 | AI18: =IF(AG18="A",0,VLOOKUP(AH18,'Transmutation Table'!$A$2:$B$32,2)) -> 70 | AJ18: =AI18*$AJ$13 -> 4.6666667 | AL18: =IFERROR(AK18/$AK$13*100,0) -> 0 | AM18: =IF(AK18="A",0,VLOOKUP(AL18,'Transmutation Table'!$A$2:$B$32,2)) -> 70 | AN18: =AM18*$AN$13 -> 4.6666667 | AP18: =IFERROR(AO18/$AO$13*100,0) -> 0 | AQ18: =IF(AO18="A",0,VLOOKUP(AP18,'Transmutation Table'!$A$2:$B$32,2)) -> 70 | AR18: =AQ18*$AR$13 -> 4.6666667 | AS18: =SUM(AJ18,AN18,AR18) -> 14 | AT18: =AVERAGE(AH18,AL18,AP18) -> 0 | AU18: =AVERAGE(AI18,AM18,AQ18) -> 70 | AV18: =SUM(S18,AF18,AS18) -> 26 | AY18: =SUM(AW18:AX18) -> 0 | AZ18: =50+(AY18/$AY$13)*50 -> 50 | BA18: =AZ18*$BA$13 -> 2.5 | BC18: =IFERROR(BB18/$T$13*100,0) -> 0 | BD18: =IF(BB18="A",0,VLOOKUP(BC18,'Transmutation Table'!$A$2:$B$32,2)) -> 70 | BE18: =BD18*$BE$13 -> 2.3333333 | BG18: =IFERROR(BF18/$X$13*100,0) -> 0 | BH18: =IF(BF18="A",0,VLOOKUP(BG18,'Transmutation Table'!$A$2:$B$32,2)) -> 70 | BI18: =BH18*$BI$13 -> 2.3333333 | BK18: =IFERROR(BJ18/#REF!*100,0) -> 0 | BL18: =IF(BJ18="A",0,VLOOKUP(BK18,'Transmutation Table'!$A$2:$B$32,2)) -> 70 | BM18: =BL18*$BM$13 -> 2.3333333 | BN18: =SUM(BE18,BI18,BM18) -> 7 | BO18: =AVERAGE(AY18) -> 0 | BP18: =AZ18 -> 50 | BQ18: =SUM(BA18,BN18) -> 9.5 | BR18: =SUM(G18,AV18,BQ18) -> 70.5 | BS18: =IFERROR(VLOOKUP(BR18,'Transmutation Table'!$B$2:$V$32,2),5) -> 5 | BT18: =IF(BR18>=75,"PASSED","FAILED") -> FAILED
A19: 6 | B19: Student 6 | E19: =_xlfn.CONCAT("/","",$F$12,"","") -> /10 | F19: =IFERROR(VLOOKUP((D19/$F$12)*100,'Transmutation Table'!$A$2:$B$32,2),0) -> 70 | G19: =$G$12*F19 -> 35 | O19: =COUNTIF(H19:N19,"P")+COUNTIF(H19:N19,"E")+COUNTIF(H19:N19,"L")*(1/3) -> 0 | P19: =COUNTA(H19:N19) -> 0 | Q19: =(P19-O19)*$Q$12 -> 0 | R19: =100-(Q19*$P$13) -> 100 | S19: =R19*$S$13 -> 5 | U19: =IFERROR(T19/$T$13*100,0) -> 0 | V19: =IF(T19="A",0,VLOOKUP(U19,'Transmutation Table'!$A$2:$B$32,2)) -> 70 | W19: =V19*$W$13 -> 2.3333333 | Y19: =IFERROR(X19/$X$13*100,0) -> 0 | Z19: =IF(X19="A",0,VLOOKUP(Y19,'Transmutation Table'!$A$2:$B$32,2)) -> 70 | AA19: =Z19*$AA$13 -> 2.3333333 | AC19: =IFERROR(AB19/$AB$13*100,0) -> 0 | AD19: =IF(AB19="A",0,VLOOKUP(AC19,'Transmutation Table'!$A$2:$B$32,2)) -> 70 | AE19: =AD19*$AE$13 -> 2.3333333 | AF19: =SUM(W19,AA19,AE19) -> 7 | AH19: =IFERROR(AG19/$AG$13*100,0) -> 0 | AI19: =IF(AG19="A",0,VLOOKUP(AH19,'Transmutation Table'!$A$2:$B$32,2)) -> 70 | AJ19: =AI19*$AJ$13 -> 4.6666667 | AL19: =IFERROR(AK19/$AK$13*100,0) -> 0 | AM19: =IF(AK19="A",0,VLOOKUP(AL19,'Transmutation Table'!$A$2:$B$32,2)) -> 70 | AN19: =AM19*$AN$13 -> 4.6666667 | AP19: =IFERROR(AO19/$AO$13*100,0) -> 0 | AQ19: =IF(AO19="A",0,VLOOKUP(AP19,'Transmutation Table'!$A$2:$B$32,2)) -> 70 | AR19: =AQ19*$AR$13 -> 4.6666667 | AS19: =SUM(AJ19,AN19,AR19) -> 14 | AT19: =AVERAGE(AH19,AL19,AP19) -> 0 | AU19: =AVERAGE(AI19,AM19,AQ19) -> 70 | AV19: =SUM(S19,AF19,AS19) -> 26 | AY19: =SUM(AW19:AX19) -> 0 | AZ19: =50+(AY19/$AY$13)*50 -> 50 | BA19: =AZ19*$BA$13 -> 2.5 | BC19: =IFERROR(BB19/$T$13*100,0) -> 0 | BD19: =IF(BB19="A",0,VLOOKUP(BC19,'Transmutation Table'!$A$2:$B$32,2)) -> 70 | BE19: =BD19*$BE$13 -> 2.3333333 | BG19: =IFERROR(BF19/$X$13*100,0) -> 0 | BH19: =IF(BF19="A",0,VLOOKUP(BG19,'Transmutation Table'!$A$2:$B$32,2)) -> 70 | BI19: =BH19*$BI$13 -> 2.3333333 | BK19: =IFERROR(BJ19/#REF!*100,0) -> 0 | BL19: =IF(BJ19="A",0,VLOOKUP(BK19,'Transmutation Table'!$A$2:$B$32,2)) -> 70 | BM19: =BL19*$BM$13 -> 2.3333333 | BN19: =SUM(BE19,BI19,BM19) -> 7 | BO19: =AVERAGE(AY19) -> 0 | BP19: =AZ19 -> 50 | BQ19: =SUM(BA19,BN19) -> 9.5 | BR19: =SUM(G19,AV19,BQ19) -> 70.5 | BS19: =IFERROR(VLOOKUP(BR19,'Transmutation Table'!$B$2:$V$32,2),5) -> 5 | BT19: =IF(BR19>=75,"PASSED","FAILED") -> FAILED
A20: 7 | B20: Student 7 | E20: =_xlfn.CONCAT("/","",$F$12,"","") -> /10 | F20: =IFERROR(VLOOKUP((D20/$F$12)*100,'Transmutation Table'!$A$2:$B$32,2),0) -> 70 | G20: =$G$12*F20 -> 35 | O20: =COUNTIF(H20:N20,"P")+COUNTIF(H20:N20,"E")+COUNTIF(H20:N20,"L")*(1/3) -> 0 | P20: =COUNTA(H20:N20) -> 0 | Q20: =(P20-O20)*$Q$12 -> 0 | R20: =100-(Q20*$P$13) -> 100 | S20: =R20*$S$13 -> 5 | U20: =IFERROR(T20/$T$13*100,0) -> 0 | V20: =IF(T20="A",0,VLOOKUP(U20,'Transmutation Table'!$A$2:$B$32,2)) -> 70 | W20: =V20*$W$13 -> 2.3333333 | Y20: =IFERROR(X20/$X$13*100,0) -> 0 | Z20: =IF(X20="A",0,VLOOKUP(Y20,'Transmutation Table'!$A$2:$B$32,2)) -> 70 | AA20: =Z20*$AA$13 -> 2.3333333 | AC20: =IFERROR(AB20/$AB$13*100,0) -> 0 | AD20: =IF(AB20="A",0,VLOOKUP(AC20,'Transmutation Table'!$A$2:$B$32,2)) -> 70 | AE20: =AD20*$AE$13 -> 2.3333333 | AF20: =SUM(W20,AA20,AE20) -> 7 | AH20: =IFERROR(AG20/$AG$13*100,0) -> 0 | AI20: =IF(AG20="A",0,VLOOKUP(AH20,'Transmutation Table'!$A$2:$B$32,2)) -> 70 | AJ20: =AI20*$AJ$13 -> 4.6666667 | AL20: =IFERROR(AK20/$AK$13*100,0) -> 0 | AM20: =IF(AK20="A",0,VLOOKUP(AL20,'Transmutation Table'!$A$2:$B$32,2)) -> 70 | AN20: =AM20*$AN$13 -> 4.6666667 | AP20: =IFERROR(AO20/$AO$13*100,0) -> 0 | AQ20: =IF(AO20="A",0,VLOOKUP(AP20,'Transmutation Table'!$A$2:$B$32,2)) -> 70 | AR20: =AQ20*$AR$13 -> 4.6666667 | AS20: =SUM(AJ20,AN20,AR20) -> 14 | AT20: =AVERAGE(AH20,AL20,AP20) -> 0 | AU20: =AVERAGE(AI20,AM20,AQ20) -> 70 | AV20: =SUM(S20,AF20,AS20) -> 26 | AY20: =SUM(AW20:AX20) -> 0 | AZ20: =50+(AY20/$AY$13)*50 -> 50 | BA20: =AZ20*$BA$13 -> 2.5 | BC20: =IFERROR(BB20/$T$13*100,0) -> 0 | BD20: =IF(BB20="A",0,VLOOKUP(BC20,'Transmutation Table'!$A$2:$B$32,2)) -> 70 | BE20: =BD20*$BE$13 -> 2.3333333 | BG20: =IFERROR(BF20/$X$13*100,0) -> 0 | BH20: =IF(BF20="A",0,VLOOKUP(BG20,'Transmutation Table'!$A$2:$B$32,2)) -> 70 | BI20: =BH20*$BI$13 -> 2.3333333 | BK20: =IFERROR(BJ20/#REF!*100,0) -> 0 | BL20: =IF(BJ20="A",0,VLOOKUP(BK20,'Transmutation Table'!$A$2:$B$32,2)) -> 70 | BM20: =BL20*$BM$13 -> 2.3333333 | BN20: =SUM(BE20,BI20,BM20) -> 7 | BO20: =AVERAGE(AY20) -> 0 | BP20: =AZ20 -> 50 | BQ20: =SUM(BA20,BN20) -> 9.5 | BR20: =SUM(G20,AV20,BQ20) -> 70.5 | BS20: =IFERROR(VLOOKUP(BR20,'Transmutation Table'!$B$2:$V$32,2),5) -> 5 | BT20: =IF(BR20>=75,"PASSED","FAILED") -> FAILED
A21: 8 | B21: Student 8 | E21: =_xlfn.CONCAT("/","",$F$12,"","") -> /10 | F21: =IFERROR(VLOOKUP((D21/$F$12)*100,'Transmutation Table'!$A$2:$B$32,2),0) -> 70 | G21: =$G$12*F21 -> 35 | O21: =COUNTIF(H21:N21,"P")+COUNTIF(H21:N21,"E")+COUNTIF(H21:N21,"L")*(1/3) -> 0 | P21: =COUNTA(H21:N21) -> 0 | Q21: =(P21-O21)*$Q$12 -> 0 | R21: =100-(Q21*$P$13) -> 100 | S21: =R21*$S$13 -> 5 | U21: =IFERROR(T21/$T$13*100,0) -> 0 | V21: =IF(T21="A",0,VLOOKUP(U21,'Transmutation Table'!$A$2:$B$32,2)) -> 70 | W21: =V21*$W$13 -> 2.3333333 | Y21: =IFERROR(X21/$X$13*100,0) -> 0 | Z21: =IF(X21="A",0,VLOOKUP(Y21,'Transmutation Table'!$A$2:$B$32,2)) -> 70 | AA21: =Z21*$AA$13 -> 2.3333333 | AC21: =IFERROR(AB21/$AB$13*100,0) -> 0 | AD21: =IF(AB21="A",0,VLOOKUP(AC21,'Transmutation Table'!$A$2:$B$32,2)) -> 70 | AE21: =AD21*$AE$13 -> 2.3333333 | AF21: =SUM(W21,AA21,AE21) -> 7 | AH21: =IFERROR(AG21/$AG$13*100,0) -> 0 | AI21: =IF(AG21="A",0,VLOOKUP(AH21,'Transmutation Table'!$A$2:$B$32,2)) -> 70 | AJ21: =AI21*$AJ$13 -> 4.6666667 | AL21: =IFERROR(AK21/$AK$13*100,0) -> 0 | AM21: =IF(AK21="A",0,VLOOKUP(AL21,'Transmutation Table'!$A$2:$B$32,2)) -> 70 | AN21: =AM21*$AN$13 -> 4.6666667 | AP21: =IFERROR(AO21/$AO$13*100,0) -> 0 | AQ21: =IF(AO21="A",0,VLOOKUP(AP21,'Transmutation Table'!$A$2:$B$32,2)) -> 70 | AR21: =AQ21*$AR$13 -> 4.6666667 | AS21: =SUM(AJ21,AN21,AR21) -> 14 | AT21: =AVERAGE(AH21,AL21,AP21) -> 0 | AU21: =AVERAGE(AI21,AM21,AQ21) -> 70 | AV21: =SUM(S21,AF21,AS21) -> 26 | AY21: =SUM(AW21:AX21) -> 0 | AZ21: =50+(AY21/$AY$13)*50 -> 50 | BA21: =AZ21*$BA$13 -> 2.5 | BC21: =IFERROR(BB21/$T$13*100,0) -> 0 | BD21: =IF(BB21="A",0,VLOOKUP(BC21,'Transmutation Table'!$A$2:$B$32,2)) -> 70 | BE21: =BD21*$BE$13 -> 2.3333333 | BG21: =IFERROR(BF21/$X$13*100,0) -> 0 | BH21: =IF(BF21="A",0,VLOOKUP(BG21,'Transmutation Table'!$A$2:$B$32,2)) -> 70 | BI21: =BH21*$BI$13 -> 2.3333333 | BK21: =IFERROR(BJ21/#REF!*100,0) -> 0 | BL21: =IF(BJ21="A",0,VLOOKUP(BK21,'Transmutation Table'!$A$2:$B$32,2)) -> 70 | BM21: =BL21*$BM$13 -> 2.3333333 | BN21: =SUM(BE21,BI21,BM21) -> 7 | BO21: =AVERAGE(AY21) -> 0 | BP21: =AZ21 -> 50 | BQ21: =SUM(BA21,BN21) -> 9.5 | BR21: =SUM(G21,AV21,BQ21) -> 70.5 | BS21: =IFERROR(VLOOKUP(BR21,'Transmutation Table'!$B$2:$V$32,2),5) -> 5 | BT21: =IF(BR21>=75,"PASSED","FAILED") -> FAILED | BV21: Permit
A22: 9 | B22: Student 9 | E22: =_xlfn.CONCAT("/","",$F$12,"","") -> /10 | F22: =IFERROR(VLOOKUP((D22/$F$12)*100,'Transmutation Table'!$A$2:$B$32,2),0) -> 70 | G22: =$G$12*F22 -> 35 | O22: =COUNTIF(H22:N22,"P")+COUNTIF(H22:N22,"E")+COUNTIF(H22:N22,"L")*(1/3) -> 0 | P22: =COUNTA(H22:N22) -> 0 | Q22: =(P22-O22)*$Q$12 -> 0 | R22: =100-(Q22*$P$13) -> 100 | S22: =R22*$S$13 -> 5 | U22: =IFERROR(T22/$T$13*100,0) -> 0 | V22: =IF(T22="A",0,VLOOKUP(U22,'Transmutation Table'!$A$2:$B$32,2)) -> 70 | W22: =V22*$W$13 -> 2.3333333 | Y22: =IFERROR(X22/$X$13*100,0) -> 0 | Z22: =IF(X22="A",0,VLOOKUP(Y22,'Transmutation Table'!$A$2:$B$32,2)) -> 70 | AA22: =Z22*$AA$13 -> 2.3333333 | AC22: =IFERROR(AB22/$AB$13*100,0) -> 0 | AD22: =IF(AB22="A",0,VLOOKUP(AC22,'Transmutation Table'!$A$2:$B$32,2)) -> 70 | AE22: =AD22*$AE$13 -> 2.3333333 | AF22: =SUM(W22,AA22,AE22) -> 7 | AH22: =IFERROR(AG22/$AG$13*100,0) -> 0 | AI22: =IF(AG22="A",0,VLOOKUP(AH22,'Transmutation Table'!$A$2:$B$32,2)) -> 70 | AJ22: =AI22*$AJ$13 -> 4.6666667 | AL22: =IFERROR(AK22/$AK$13*100,0) -> 0 | AM22: =IF(AK22="A",0,VLOOKUP(AL22,'Transmutation Table'!$A$2:$B$32,2)) -> 70 | AN22: =AM22*$AN$13 -> 4.6666667 | AP22: =IFERROR(AO22/$AO$13*100,0) -> 0 | AQ22: =IF(AO22="A",0,VLOOKUP(AP22,'Transmutation Table'!$A$2:$B$32,2)) -> 70 | AR22: =AQ22*$AR$13 -> 4.6666667 | AS22: =SUM(AJ22,AN22,AR22) -> 14 | AT22: =AVERAGE(AH22,AL22,AP22) -> 0 | AU22: =AVERAGE(AI22,AM22,AQ22) -> 70 | AV22: =SUM(S22,AF22,AS22) -> 26 | AY22: =SUM(AW22:AX22) -> 0 | AZ22: =50+(AY22/$AY$13)*50 -> 50 | BA22: =AZ22*$BA$13 -> 2.5 | BC22: =IFERROR(BB22/$T$13*100,0) -> 0 | BD22: =IF(BB22="A",0,VLOOKUP(BC22,'Transmutation Table'!$A$2:$B$32,2)) -> 70 | BE22: =BD22*$BE$13 -> 2.3333333 | BG22: =IFERROR(BF22/$X$13*100,0) -> 0 | BH22: =IF(BF22="A",0,VLOOKUP(BG22,'Transmutation Table'!$A$2:$B$32,2)) -> 70 | BI22: =BH22*$BI$13 -> 2.3333333 | BK22: =IFERROR(BJ22/#REF!*100,0) -> 0 | BL22: =IF(BJ22="A",0,VLOOKUP(BK22,'Transmutation Table'!$A$2:$B$32,2)) -> 70 | BM22: =BL22*$BM$13 -> 2.3333333 | BN22: =SUM(BE22,BI22,BM22) -> 7 | BO22: =AVERAGE(AY22) -> 0 | BP22: =AZ22 -> 50 | BQ22: =SUM(BA22,BN22) -> 9.5 | BR22: =SUM(G22,AV22,BQ22) -> 70.5 | BS22: =IFERROR(VLOOKUP(BR22,'Transmutation Table'!$B$2:$V$32,2),5) -> 5 | BT22: =IF(BR22>=75,"PASSED","FAILED") -> FAILED
A23: 10 | B23: Student 10 | E23: =_xlfn.CONCAT("/","",$F$12,"","") -> /10 | F23: =IFERROR(VLOOKUP((D23/$F$12)*100,'Transmutation Table'!$A$2:$B$32,2),0) -> 70 | G23: =$G$12*F23 -> 35 | O23: =COUNTIF(H23:N23,"P")+COUNTIF(H23:N23,"E")+COUNTIF(H23:N23,"L")*(1/3) -> 0 | P23: =COUNTA(H23:N23) -> 0 | Q23: =(P23-O23)*$Q$12 -> 0 | R23: =100-(Q23*$P$13) -> 100 | S23: =R23*$S$13 -> 5 | U23: =IFERROR(T23/$T$13*100,0) -> 0 | V23: =IF(T23="A",0,VLOOKUP(U23,'Transmutation Table'!$A$2:$B$32,2)) -> 70 | W23: =V23*$W$13 -> 2.3333333 | Y23: =IFERROR(X23/$X$13*100,0) -> 0 | Z23: =IF(X23="A",0,VLOOKUP(Y23,'Transmutation Table'!$A$2:$B$32,2)) -> 70 | AA23: =Z23*$AA$13 -> 2.3333333 | AC23: =IFERROR(AB23/$AB$13*100,0) -> 0 | AD23: =IF(AB23="A",0,VLOOKUP(AC23,'Transmutation Table'!$A$2:$B$32,2)) -> 70 | AE23: =AD23*$AE$13 -> 2.3333333 | AF23: =SUM(W23,AA23,AE23) -> 7 | AH23: =IFERROR(AG23/$AG$13*100,0) -> 0 | AI23: =IF(AG23="A",0,VLOOKUP(AH23,'Transmutation Table'!$A$2:$B$32,2)) -> 70 | AJ23: =AI23*$AJ$13 -> 4.6666667 | AL23: =IFERROR(AK23/$AK$13*100,0) -> 0 | AM23: =IF(AK23="A",0,VLOOKUP(AL23,'Transmutation Table'!$A$2:$B$32,2)) -> 70 | AN23: =AM23*$AN$13 -> 4.6666667 | AP23: =IFERROR(AO23/$AO$13*100,0) -> 0 | AQ23: =IF(AO23="A",0,VLOOKUP(AP23,'Transmutation Table'!$A$2:$B$32,2)) -> 70 | AR23: =AQ23*$AR$13 -> 4.6666667 | AS23: =SUM(AJ23,AN23,AR23) -> 14 | AT23: =AVERAGE(AH23,AL23,AP23) -> 0 | AU23: =AVERAGE(AI23,AM23,AQ23) -> 70 | AV23: =SUM(S23,AF23,AS23) -> 26 | AY23: =SUM(AW23:AX23) -> 0 | AZ23: =50+(AY23/$AY$13)*50 -> 50 | BA23: =AZ23*$BA$13 -> 2.5 | BC23: =IFERROR(BB23/$T$13*100,0) -> 0 | BD23: =IF(BB23="A",0,VLOOKUP(BC23,'Transmutation Table'!$A$2:$B$32,2)) -> 70 | BE23: =BD23*$BE$13 -> 2.3333333 | BG23: =IFERROR(BF23/$X$13*100,0) -> 0 | BH23: =IF(BF23="A",0,VLOOKUP(BG23,'Transmutation Table'!$A$2:$B$32,2)) -> 70 | BI23: =BH23*$BI$13 -> 2.3333333 | BK23: =IFERROR(BJ23/#REF!*100,0) -> 0 | BL23: =IF(BJ23="A",0,VLOOKUP(BK23,'Transmutation Table'!$A$2:$B$32,2)) -> 70 | BM23: =BL23*$BM$13 -> 2.3333333 | BN23: =SUM(BE23,BI23,BM23) -> 7 | BO23: =AVERAGE(AY23) -> 0 | BP23: =AZ23 -> 50 | BQ23: =SUM(BA23,BN23) -> 9.5 | BR23: =SUM(G23,AV23,BQ23) -> 70.5 | BS23: =IFERROR(VLOOKUP(BR23,'Transmutation Table'!$B$2:$V$32,2),5) -> 5 | BT23: =IF(BR23>=75,"PASSED","FAILED") -> FAILED
A24: 11 | B24: Student 11 | E24: =_xlfn.CONCAT("/","",$F$12,"","") -> /10 | F24: =IFERROR(VLOOKUP((D24/$F$12)*100,'Transmutation Table'!$A$2:$B$32,2),0) -> 70 | G24: =$G$12*F24 -> 35 | O24: =COUNTIF(H24:N24,"P")+COUNTIF(H24:N24,"E")+COUNTIF(H24:N24,"L")*(1/3) -> 0 | P24: =COUNTA(H24:N24) -> 0 | Q24: =(P24-O24)*$Q$12 -> 0 | R24: =100-(Q24*$P$13) -> 100 | S24: =R24*$S$13 -> 5 | U24: =IFERROR(T24/$T$13*100,0) -> 0 | V24: =IF(T24="A",0,VLOOKUP(U24,'Transmutation Table'!$A$2:$B$32,2)) -> 70 | W24: =V24*$W$13 -> 2.3333333 | Y24: =IFERROR(X24/$X$13*100,0) -> 0 | Z24: =IF(X24="A",0,VLOOKUP(Y24,'Transmutation Table'!$A$2:$B$32,2)) -> 70 | AA24: =Z24*$AA$13 -> 2.3333333 | AC24: =IFERROR(AB24/$AB$13*100,0) -> 0 | AD24: =IF(AB24="A",0,VLOOKUP(AC24,'Transmutation Table'!$A$2:$B$32,2)) -> 70 | AE24: =AD24*$AE$13 -> 2.3333333 | AF24: =SUM(W24,AA24,AE24) -> 7 | AH24: =IFERROR(AG24/$AG$13*100,0) -> 0 | AI24: =IF(AG24="A",0,VLOOKUP(AH24,'Transmutation Table'!$A$2:$B$32,2)) -> 70 | AJ24: =AI24*$AJ$13 -> 4.6666667 | AL24: =IFERROR(AK24/$AK$13*100,0) -> 0 | AM24: =IF(AK24="A",0,VLOOKUP(AL24,'Transmutation Table'!$A$2:$B$32,2)) -> 70 | AN24: =AM24*$AN$13 -> 4.6666667 | AP24: =IFERROR(AO24/$AO$13*100,0) -> 0 | AQ24: =IF(AO24="A",0,VLOOKUP(AP24,'Transmutation Table'!$A$2:$B$32,2)) -> 70 | AR24: =AQ24*$AR$13 -> 4.6666667 | AS24: =SUM(AJ24,AN24,AR24) -> 14 | AT24: =AVERAGE(AH24,AL24,AP24) -> 0 | AU24: =AVERAGE(AI24,AM24,AQ24) -> 70 | AV24: =SUM(S24,AF24,AS24) -> 26 | AY24: =SUM(AW24:AX24) -> 0 | AZ24: =50+(AY24/$AY$13)*50 -> 50 | BA24: =AZ24*$BA$13 -> 2.5 | BC24: =IFERROR(BB24/$T$13*100,0) -> 0 | BD24: =IF(BB24="A",0,VLOOKUP(BC24,'Transmutation Table'!$A$2:$B$32,2)) -> 70 | BE24: =BD24*$BE$13 -> 2.3333333 | BG24: =IFERROR(BF24/$X$13*100,0) -> 0 | BH24: =IF(BF24="A",0,VLOOKUP(BG24,'Transmutation Table'!$A$2:$B$32,2)) -> 70 | BI24: =BH24*$BI$13 -> 2.3333333 | BK24: =IFERROR(BJ24/#REF!*100,0) -> 0 | BL24: =IF(BJ24="A",0,VLOOKUP(BK24,'Transmutation Table'!$A$2:$B$32,2)) -> 70 | BM24: =BL24*$BM$13 -> 2.3333333 | BN24: =SUM(BE24,BI24,BM24) -> 7 | BO24: =AVERAGE(AY24) -> 0 | BP24: =AZ24 -> 50 | BQ24: =SUM(BA24,BN24) -> 9.5 | BR24: =SUM(G24,AV24,BQ24) -> 70.5 | BS24: =IFERROR(VLOOKUP(BR24,'Transmutation Table'!$B$2:$V$32,2),5) -> 5 | BT24: =IF(BR24>=75,"PASSED","FAILED") -> FAILED
A25: 12 | B25: Student 12 | E25: =_xlfn.CONCAT("/","",$F$12,"","") -> /10 | F25: =IFERROR(VLOOKUP((D25/$F$12)*100,'Transmutation Table'!$A$2:$B$32,2),0) -> 70 | G25: =$G$12*F25 -> 35 | O25: =COUNTIF(H25:N25,"P")+COUNTIF(H25:N25,"E")+COUNTIF(H25:N25,"L")*(1/3) -> 0 | P25: =COUNTA(H25:N25) -> 0 | Q25: =(P25-O25)*$Q$12 -> 0 | R25: =100-(Q25*$P$13) -> 100 | S25: =R25*$S$13 -> 5 | U25: =IFERROR(T25/$T$13*100,0) -> 0 | V25: =IF(T25="A",0,VLOOKUP(U25,'Transmutation Table'!$A$2:$B$32,2)) -> 70 | W25: =V25*$W$13 -> 2.3333333 | Y25: =IFERROR(X25/$X$13*100,0) -> 0 | Z25: =IF(X25="A",0,VLOOKUP(Y25,'Transmutation Table'!$A$2:$B$32,2)) -> 70 | AA25: =Z25*$AA$13 -> 2.3333333 | AC25: =IFERROR(AB25/$AB$13*100,0) -> 0 | AD25: =IF(AB25="A",0,VLOOKUP(AC25,'Transmutation Table'!$A$2:$B$32,2)) -> 70 | AE25: =AD25*$AE$13 -> 2.3333333 | AF25: =SUM(W25,AA25,AE25) -> 7 | AH25: =IFERROR(AG25/$AG$13*100,0) -> 0 | AI25: =IF(AG25="A",0,VLOOKUP(AH25,'Transmutation Table'!$A$2:$B$32,2)) -> 70 | AJ25: =AI25*$AJ$13 -> 4.6666667 | AL25: =IFERROR(AK25/$AK$13*100,0) -> 0 | AM25: =IF(AK25="A",0,VLOOKUP(AL25,'Transmutation Table'!$A$2:$B$32,2)) -> 70 | AN25: =AM25*$AN$13 -> 4.6666667 | AP25: =IFERROR(AO25/$AO$13*100,0) -> 0 | AQ25: =IF(AO25="A",0,VLOOKUP(AP25,'Transmutation Table'!$A$2:$B$32,2)) -> 70 | AR25: =AQ25*$AR$13 -> 4.6666667 | AS25: =SUM(AJ25,AN25,AR25) -> 14 | AT25: =AVERAGE(AH25,AL25,AP25) -> 0 | AU25: =AVERAGE(AI25,AM25,AQ25) -> 70 | AV25: =SUM(S25,AF25,AS25) -> 26 | AY25: =SUM(AW25:AX25) -> 0 | AZ25: =50+(AY25/$AY$13)*50 -> 50 | BA25: =AZ25*$BA$13 -> 2.5 | BC25: =IFERROR(BB25/$T$13*100,0) -> 0 | BD25: =IF(BB25="A",0,VLOOKUP(BC25,'Transmutation Table'!$A$2:$B$32,2)) -> 70 | BE25: =BD25*$BE$13 -> 2.3333333 | BG25: =IFERROR(BF25/$X$13*100,0) -> 0 | BH25: =IF(BF25="A",0,VLOOKUP(BG25,'Transmutation Table'!$A$2:$B$32,2)) -> 70 | BI25: =BH25*$BI$13 -> 2.3333333 | BK25: =IFERROR(BJ25/#REF!*100,0) -> 0 | BL25: =IF(BJ25="A",0,VLOOKUP(BK25,'Transmutation Table'!$A$2:$B$32,2)) -> 70 | BM25: =BL25*$BM$13 -> 2.3333333 | BN25: =SUM(BE25,BI25,BM25) -> 7 | BO25: =AVERAGE(AY25) -> 0 | BP25: =AZ25 -> 50 | BQ25: =SUM(BA25,BN25) -> 9.5 | BR25: =SUM(G25,AV25,BQ25) -> 70.5 | BS25: =IFERROR(VLOOKUP(BR25,'Transmutation Table'!$B$2:$V$32,2),5) -> 5 | BT25: =IF(BR25>=75,"PASSED","FAILED") -> FAILED
A26: 13 | B26: Student 13 | E26: =_xlfn.CONCAT("/","",$F$12,"","") -> /10 | F26: =IFERROR(VLOOKUP((D26/$F$12)*100,'Transmutation Table'!$A$2:$B$32,2),0) -> 70 | G26: =$G$12*F26 -> 35 | O26: =COUNTIF(H26:N26,"P")+COUNTIF(H26:N26,"E")+COUNTIF(H26:N26,"L")*(1/3) -> 0 | P26: =COUNTA(H26:N26) -> 0 | Q26: =(P26-O26)*$Q$12 -> 0 | R26: =100-(Q26*$P$13) -> 100 | S26: =R26*$S$13 -> 5 | U26: =IFERROR(T26/$T$13*100,0) -> 0 | V26: =IF(T26="A",0,VLOOKUP(U26,'Transmutation Table'!$A$2:$B$32,2)) -> 70 | W26: =V26*$W$13 -> 2.3333333 | Y26: =IFERROR(X26/$X$13*100,0) -> 0 | Z26: =IF(X26="A",0,VLOOKUP(Y26,'Transmutation Table'!$A$2:$B$32,2)) -> 70 | AA26: =Z26*$AA$13 -> 2.3333333 | AC26: =IFERROR(AB26/$AB$13*100,0) -> 0 | AD26: =IF(AB26="A",0,VLOOKUP(AC26,'Transmutation Table'!$A$2:$B$32,2)) -> 70 | AE26: =AD26*$AE$13 -> 2.3333333 | AF26: =SUM(W26,AA26,AE26) -> 7 | AH26: =IFERROR(AG26/$AG$13*100,0) -> 0 | AI26: =IF(AG26="A",0,VLOOKUP(AH26,'Transmutation Table'!$A$2:$B$32,2)) -> 70 | AJ26: =AI26*$AJ$13 -> 4.6666667 | AL26: =IFERROR(AK26/$AK$13*100,0) -> 0 | AM26: =IF(AK26="A",0,VLOOKUP(AL26,'Transmutation Table'!$A$2:$B$32,2)) -> 70 | AN26: =AM26*$AN$13 -> 4.6666667 | AP26: =IFERROR(AO26/$AO$13*100,0) -> 0 | AQ26: =IF(AO26="A",0,VLOOKUP(AP26,'Transmutation Table'!$A$2:$B$32,2)) -> 70 | AR26: =AQ26*$AR$13 -> 4.6666667 | AS26: =SUM(AJ26,AN26,AR26) -> 14 | AT26: =AVERAGE(AH26,AL26,AP26) -> 0 | AU26: =AVERAGE(AI26,AM26,AQ26) -> 70 | AV26: =SUM(S26,AF26,AS26) -> 26 | AY26: =SUM(AW26:AX26) -> 0 | AZ26: =50+(AY26/$AY$13)*50 -> 50 | BA26: =AZ26*$BA$13 -> 2.5 | BC26: =IFERROR(BB26/$T$13*100,0) -> 0 | BD26: =IF(BB26="A",0,VLOOKUP(BC26,'Transmutation Table'!$A$2:$B$32,2)) -> 70 | BE26: =BD26*$BE$13 -> 2.3333333 | BG26: =IFERROR(BF26/$X$13*100,0) -> 0 | BH26: =IF(BF26="A",0,VLOOKUP(BG26,'Transmutation Table'!$A$2:$B$32,2)) -> 70 | BI26: =BH26*$BI$13 -> 2.3333333 | BK26: =IFERROR(BJ26/#REF!*100,0) -> 0 | BL26: =IF(BJ26="A",0,VLOOKUP(BK26,'Transmutation Table'!$A$2:$B$32,2)) -> 70 | BM26: =BL26*$BM$13 -> 2.3333333 | BN26: =SUM(BE26,BI26,BM26) -> 7 | BO26: =AVERAGE(AY26) -> 0 | BP26: =AZ26 -> 50 | BQ26: =SUM(BA26,BN26) -> 9.5 | BR26: =SUM(G26,AV26,BQ26) -> 70.5 | BS26: =IFERROR(VLOOKUP(BR26,'Transmutation Table'!$B$2:$V$32,2),5) -> 5 | BT26: =IF(BR26>=75,"PASSED","FAILED") -> FAILED
A27: 14 | B27: Student 14 | E27: =_xlfn.CONCAT("/","",$F$12,"","") -> /10 | F27: =IFERROR(VLOOKUP((D27/$F$12)*100,'Transmutation Table'!$A$2:$B$32,2),0) -> 70 | G27: =$G$12*F27 -> 35 | O27: =COUNTIF(H27:N27,"P")+COUNTIF(H27:N27,"E")+COUNTIF(H27:N27,"L")*(1/3) -> 0 | P27: =COUNTA(H27:N27) -> 0 | Q27: =(P27-O27)*$Q$12 -> 0 | R27: =100-(Q27*$P$13) -> 100 | S27: =R27*$S$13 -> 5 | U27: =IFERROR(T27/$T$13*100,0) -> 0 | V27: =IF(T27="A",0,VLOOKUP(U27,'Transmutation Table'!$A$2:$B$32,2)) -> 70 | W27: =V27*$W$13 -> 2.3333333 | Y27: =IFERROR(X27/$X$13*100,0) -> 0 | Z27: =IF(X27="A",0,VLOOKUP(Y27,'Transmutation Table'!$A$2:$B$32,2)) -> 70 | AA27: =Z27*$AA$13 -> 2.3333333 | AC27: =IFERROR(AB27/$AB$13*100,0) -> 0 | AD27: =IF(AB27="A",0,VLOOKUP(AC27,'Transmutation Table'!$A$2:$B$32,2)) -> 70 | AE27: =AD27*$AE$13 -> 2.3333333 | AF27: =SUM(W27,AA27,AE27) -> 7 | AH27: =IFERROR(AG27/$AG$13*100,0) -> 0 | AI27: =IF(AG27="A",0,VLOOKUP(AH27,'Transmutation Table'!$A$2:$B$32,2)) -> 70 | AJ27: =AI27*$AJ$13 -> 4.6666667 | AL27: =IFERROR(AK27/$AK$13*100,0) -> 0 | AM27: =IF(AK27="A",0,VLOOKUP(AL27,'Transmutation Table'!$A$2:$B$32,2)) -> 70 | AN27: =AM27*$AN$13 -> 4.6666667 | AP27: =IFERROR(AO27/$AO$13*100,0) -> 0 | AQ27: =IF(AO27="A",0,VLOOKUP(AP27,'Transmutation Table'!$A$2:$B$32,2)) -> 70 | AR27: =AQ27*$AR$13 -> 4.6666667 | AS27: =SUM(AJ27,AN27,AR27) -> 14 | AT27: =AVERAGE(AH27,AL27,AP27) -> 0 | AU27: =AVERAGE(AI27,AM27,AQ27) -> 70 | AV27: =SUM(S27,AF27,AS27) -> 26 | AY27: =SUM(AW27:AX27) -> 0 | AZ27: =50+(AY27/$AY$13)*50 -> 50 | BA27: =AZ27*$BA$13 -> 2.5 | BC27: =IFERROR(BB27/$T$13*100,0) -> 0 | BD27: =IF(BB27="A",0,VLOOKUP(BC27,'Transmutation Table'!$A$2:$B$32,2)) -> 70 | BE27: =BD27*$BE$13 -> 2.3333333 | BG27: =IFERROR(BF27/$X$13*100,0) -> 0 | BH27: =IF(BF27="A",0,VLOOKUP(BG27,'Transmutation Table'!$A$2:$B$32,2)) -> 70 | BI27: =BH27*$BI$13 -> 2.3333333 | BK27: =IFERROR(BJ27/#REF!*100,0) -> 0 | BL27: =IF(BJ27="A",0,VLOOKUP(BK27,'Transmutation Table'!$A$2:$B$32,2)) -> 70 | BM27: =BL27*$BM$13 -> 2.3333333 | BN27: =SUM(BE27,BI27,BM27) -> 7 | BO27: =AVERAGE(AY27) -> 0 | BP27: =AZ27 -> 50 | BQ27: =SUM(BA27,BN27) -> 9.5 | BR27: =SUM(G27,AV27,BQ27) -> 70.5 | BS27: =IFERROR(VLOOKUP(BR27,'Transmutation Table'!$B$2:$V$32,2),5) -> 5 | BT27: =IF(BR27>=75,"PASSED","FAILED") -> FAILED
A28: 15 | B28: Student 15 | E28: =_xlfn.CONCAT("/","",$F$12,"","") -> /10 | F28: =IFERROR(VLOOKUP((D28/$F$12)*100,'Transmutation Table'!$A$2:$B$32,2),0) -> 70 | G28: =$G$12*F28 -> 35 | O28: =COUNTIF(H28:N28,"P")+COUNTIF(H28:N28,"E")+COUNTIF(H28:N28,"L")*(1/3) -> 0 | P28: =COUNTA(H28:N28) -> 0 | Q28: =(P28-O28)*$Q$12 -> 0 | R28: =100-(Q28*$P$13) -> 100 | S28: =R28*$S$13 -> 5 | U28: =IFERROR(T28/$T$13*100,0) -> 0 | V28: =IF(T28="A",0,VLOOKUP(U28,'Transmutation Table'!$A$2:$B$32,2)) -> 70 | W28: =V28*$W$13 -> 2.3333333 | Y28: =IFERROR(X28/$X$13*100,0) -> 0 | Z28: =IF(X28="A",0,VLOOKUP(Y28,'Transmutation Table'!$A$2:$B$32,2)) -> 70 | AA28: =Z28*$AA$13 -> 2.3333333 | AC28: =IFERROR(AB28/$AB$13*100,0) -> 0 | AD28: =IF(AB28="A",0,VLOOKUP(AC28,'Transmutation Table'!$A$2:$B$32,2)) -> 70 | AE28: =AD28*$AE$13 -> 2.3333333 | AF28: =SUM(W28,AA28,AE28) -> 7 | AH28: =IFERROR(AG28/$AG$13*100,0) -> 0 | AI28: =IF(AG28="A",0,VLOOKUP(AH28,'Transmutation Table'!$A$2:$B$32,2)) -> 70 | AJ28: =AI28*$AJ$13 -> 4.6666667 | AL28: =IFERROR(AK28/$AK$13*100,0) -> 0 | AM28: =IF(AK28="A",0,VLOOKUP(AL28,'Transmutation Table'!$A$2:$B$32,2)) -> 70 | AN28: =AM28*$AN$13 -> 4.6666667 | AP28: =IFERROR(AO28/$AO$13*100,0) -> 0 | AQ28: =IF(AO28="A",0,VLOOKUP(AP28,'Transmutation Table'!$A$2:$B$32,2)) -> 70 | AR28: =AQ28*$AR$13 -> 4.6666667 | AS28: =SUM(AJ28,AN28,AR28) -> 14 | AT28: =AVERAGE(AH28,AL28,AP28) -> 0 | AU28: =AVERAGE(AI28,AM28,AQ28) -> 70 | AV28: =SUM(S28,AF28,AS28) -> 26 | AY28: =SUM(AW28:AX28) -> 0 | AZ28: =50+(AY28/$AY$13)*50 -> 50 | BA28: =AZ28*$BA$13 -> 2.5 | BC28: =IFERROR(BB28/$T$13*100,0) -> 0 | BD28: =IF(BB28="A",0,VLOOKUP(BC28,'Transmutation Table'!$A$2:$B$32,2)) -> 70 | BE28: =BD28*$BE$13 -> 2.3333333 | BG28: =IFERROR(BF28/$X$13*100,0) -> 0 | BH28: =IF(BF28="A",0,VLOOKUP(BG28,'Transmutation Table'!$A$2:$B$32,2)) -> 70 | BI28: =BH28*$BI$13 -> 2.3333333 | BK28: =IFERROR(BJ28/#REF!*100,0) -> 0 | BL28: =IF(BJ28="A",0,VLOOKUP(BK28,'Transmutation Table'!$A$2:$B$32,2)) -> 70 | BM28: =BL28*$BM$13 -> 2.3333333 | BN28: =SUM(BE28,BI28,BM28) -> 7 | BO28: =AVERAGE(AY28) -> 0 | BP28: =AZ28 -> 50 | BQ28: =SUM(BA28,BN28) -> 9.5 | BR28: =SUM(G28,AV28,BQ28) -> 70.5 | BS28: =IFERROR(VLOOKUP(BR28,'Transmutation Table'!$B$2:$V$32,2),5) -> 5 | BT28: =IF(BR28>=75,"PASSED","FAILED") -> FAILED
A29: 16 | B29: Student 16 | E29: =_xlfn.CONCAT("/","",$F$12,"","") -> /10 | F29: =IFERROR(VLOOKUP((D29/$F$12)*100,'Transmutation Table'!$A$2:$B$32,2),0) -> 70 | G29: =$G$12*F29 -> 35 | O29: =COUNTIF(H29:N29,"P")+COUNTIF(H29:N29,"E")+COUNTIF(H29:N29,"L")*(1/3) -> 0 | P29: =COUNTA(H29:N29) -> 0 | Q29: =(P29-O29)*$Q$12 -> 0 | R29: =100-(Q29*$P$13) -> 100 | S29: =R29*$S$13 -> 5 | U29: =IFERROR(T29/$T$13*100,0) -> 0 | V29: =IF(T29="A",0,VLOOKUP(U29,'Transmutation Table'!$A$2:$B$32,2)) -> 70 | W29: =V29*$W$13 -> 2.3333333 | Y29: =IFERROR(X29/$X$13*100,0) -> 0 | Z29: =IF(X29="A",0,VLOOKUP(Y29,'Transmutation Table'!$A$2:$B$32,2)) -> 70 | AA29: =Z29*$AA$13 -> 2.3333333 | AC29: =IFERROR(AB29/$AB$13*100,0) -> 0 | AD29: =IF(AB29="A",0,VLOOKUP(AC29,'Transmutation Table'!$A$2:$B$32,2)) -> 70 | AE29: =AD29*$AE$13 -> 2.3333333 | AF29: =SUM(W29,AA29,AE29) -> 7 | AH29: =IFERROR(AG29/$AG$13*100,0) -> 0 | AI29: =IF(AG29="A",0,VLOOKUP(AH29,'Transmutation Table'!$A$2:$B$32,2)) -> 70 | AJ29: =AI29*$AJ$13 -> 4.6666667 | AL29: =IFERROR(AK29/$AK$13*100,0) -> 0 | AM29: =IF(AK29="A",0,VLOOKUP(AL29,'Transmutation Table'!$A$2:$B$32,2)) -> 70 | AN29: =AM29*$AN$13 -> 4.6666667 | AP29: =IFERROR(AO29/$AO$13*100,0) -> 0 | AQ29: =IF(AO29="A",0,VLOOKUP(AP29,'Transmutation Table'!$A$2:$B$32,2)) -> 70 | AR29: =AQ29*$AR$13 -> 4.6666667 | AS29: =SUM(AJ29,AN29,AR29) -> 14 | AT29: =AVERAGE(AH29,AL29,AP29) -> 0 | AU29: =AVERAGE(AI29,AM29,AQ29) -> 70 | AV29: =SUM(S29,AF29,AS29) -> 26 | AY29: =SUM(AW29:AX29) -> 0 | AZ29: =50+(AY29/$AY$13)*50 -> 50 | BA29: =AZ29*$BA$13 -> 2.5 | BC29: =IFERROR(BB29/$T$13*100,0) -> 0 | BD29: =IF(BB29="A",0,VLOOKUP(BC29,'Transmutation Table'!$A$2:$B$32,2)) -> 70 | BE29: =BD29*$BE$13 -> 2.3333333 | BG29: =IFERROR(BF29/$X$13*100,0) -> 0 | BH29: =IF(BF29="A",0,VLOOKUP(BG29,'Transmutation Table'!$A$2:$B$32,2)) -> 70 | BI29: =BH29*$BI$13 -> 2.3333333 | BK29: =IFERROR(BJ29/#REF!*100,0) -> 0 | BL29: =IF(BJ29="A",0,VLOOKUP(BK29,'Transmutation Table'!$A$2:$B$32,2)) -> 70 | BM29: =BL29*$BM$13 -> 2.3333333 | BN29: =SUM(BE29,BI29,BM29) -> 7 | BO29: =AVERAGE(AY29) -> 0 | BP29: =AZ29 -> 50 | BQ29: =SUM(BA29,BN29) -> 9.5 | BR29: =SUM(G29,AV29,BQ29) -> 70.5 | BS29: =IFERROR(VLOOKUP(BR29,'Transmutation Table'!$B$2:$V$32,2),5) -> 5 | BT29: =IF(BR29>=75,"PASSED","FAILED") -> FAILED
A30: 17 | B30: Student 17 | E30: =_xlfn.CONCAT("/","",$F$12,"","") -> /10 | F30: =IFERROR(VLOOKUP((D30/$F$12)*100,'Transmutation Table'!$A$2:$B$32,2),0) -> 70 | G30: =$G$12*F30 -> 35 | O30: =COUNTIF(H30:N30,"P")+COUNTIF(H30:N30,"E")+COUNTIF(H30:N30,"L")*(1/3) -> 0 | P30: =COUNTA(H30:N30) -> 0 | Q30: =(P30-O30)*$Q$12 -> 0 | R30: =100-(Q30*$P$13) -> 100 | S30: =R30*$S$13 -> 5 | U30: =IFERROR(T30/$T$13*100,0) -> 0 | V30: =IF(T30="A",0,VLOOKUP(U30,'Transmutation Table'!$A$2:$B$32,2)) -> 70 | W30: =V30*$W$13 -> 2.3333333 | Y30: =IFERROR(X30/$X$13*100,0) -> 0 | Z30: =IF(X30="A",0,VLOOKUP(Y30,'Transmutation Table'!$A$2:$B$32,2)) -> 70 | AA30: =Z30*$AA$13 -> 2.3333333 | AC30: =IFERROR(AB30/$AB$13*100,0) -> 0 | AD30: =IF(AB30="A",0,VLOOKUP(AC30,'Transmutation Table'!$A$2:$B$32,2)) -> 70 | AE30: =AD30*$AE$13 -> 2.3333333 | AF30: =SUM(W30,AA30,AE30) -> 7 | AH30: =IFERROR(AG30/$AG$13*100,0) -> 0 | AI30: =IF(AG30="A",0,VLOOKUP(AH30,'Transmutation Table'!$A$2:$B$32,2)) -> 70 | AJ30: =AI30*$AJ$13 -> 4.6666667 | AL30: =IFERROR(AK30/$AK$13*100,0) -> 0 | AM30: =IF(AK30="A",0,VLOOKUP(AL30,'Transmutation Table'!$A$2:$B$32,2)) -> 70 | AN30: =AM30*$AN$13 -> 4.6666667 | AP30: =IFERROR(AO30/$AO$13*100,0) -> 0 | AQ30: =IF(AO30="A",0,VLOOKUP(AP30,'Transmutation Table'!$A$2:$B$32,2)) -> 70 | AR30: =AQ30*$AR$13 -> 4.6666667 | AS30: =SUM(AJ30,AN30,AR30) -> 14 | AT30: =AVERAGE(AH30,AL30,AP30) -> 0 | AU30: =AVERAGE(AI30,AM30,AQ30) -> 70 | AV30: =SUM(S30,AF30,AS30) -> 26 | AY30: =SUM(AW30:AX30) -> 0 | AZ30: =50+(AY30/$AY$13)*50 -> 50 | BA30: =AZ30*$BA$13 -> 2.5 | BC30: =IFERROR(BB30/$T$13*100,0) -> 0 | BD30: =IF(BB30="A",0,VLOOKUP(BC30,'Transmutation Table'!$A$2:$B$32,2)) -> 70 | BE30: =BD30*$BE$13 -> 2.3333333 | BG30: =IFERROR(BF30/$X$13*100,0) -> 0 | BH30: =IF(BF30="A",0,VLOOKUP(BG30,'Transmutation Table'!$A$2:$B$32,2)) -> 70 | BI30: =BH30*$BI$13 -> 2.3333333 | BK30: =IFERROR(BJ30/#REF!*100,0) -> 0 | BL30: =IF(BJ30="A",0,VLOOKUP(BK30,'Transmutation Table'!$A$2:$B$32,2)) -> 70 | BM30: =BL30*$BM$13 -> 2.3333333 | BN30: =SUM(BE30,BI30,BM30) -> 7 | BO30: =AVERAGE(AY30) -> 0 | BP30: =AZ30 -> 50 | BQ30: =SUM(BA30,BN30) -> 9.5 | BR30: =SUM(G30,AV30,BQ30) -> 70.5 | BS30: =IFERROR(VLOOKUP(BR30,'Transmutation Table'!$B$2:$V$32,2),5) -> 5 | BT30: =IF(BR30>=75,"PASSED","FAILED") -> FAILED
A31: 18 | B31: Student 18 | E31: =_xlfn.CONCAT("/","",$F$12,"","") -> /10 | F31: =IFERROR(VLOOKUP((D31/$F$12)*100,'Transmutation Table'!$A$2:$B$32,2),0) -> 70 | G31: =$G$12*F31 -> 35 | O31: =COUNTIF(H31:N31,"P")+COUNTIF(H31:N31,"E")+COUNTIF(H31:N31,"L")*(1/3) -> 0 | P31: =COUNTA(H31:N31) -> 0 | Q31: =(P31-O31)*$Q$12 -> 0 | R31: =100-(Q31*$P$13) -> 100 | S31: =R31*$S$13 -> 5 | U31: =IFERROR(T31/$T$13*100,0) -> 0 | V31: =IF(T31="A",0,VLOOKUP(U31,'Transmutation Table'!$A$2:$B$32,2)) -> 70 | W31: =V31*$W$13 -> 2.3333333 | Y31: =IFERROR(X31/$X$13*100,0) -> 0 | Z31: =IF(X31="A",0,VLOOKUP(Y31,'Transmutation Table'!$A$2:$B$32,2)) -> 70 | AA31: =Z31*$AA$13 -> 2.3333333 | AC31: =IFERROR(AB31/$AB$13*100,0) -> 0 | AD31: =IF(AB31="A",0,VLOOKUP(AC31,'Transmutation Table'!$A$2:$B$32,2)) -> 70 | AE31: =AD31*$AE$13 -> 2.3333333 | AF31: =SUM(W31,AA31,AE31) -> 7 | AH31: =IFERROR(AG31/$AG$13*100,0) -> 0 | AI31: =IF(AG31="A",0,VLOOKUP(AH31,'Transmutation Table'!$A$2:$B$32,2)) -> 70 | AJ31: =AI31*$AJ$13 -> 4.6666667 | AL31: =IFERROR(AK31/$AK$13*100,0) -> 0 | AM31: =IF(AK31="A",0,VLOOKUP(AL31,'Transmutation Table'!$A$2:$B$32,2)) -> 70 | AN31: =AM31*$AN$13 -> 4.6666667 | AP31: =IFERROR(AO31/$AO$13*100,0) -> 0 | AQ31: =IF(AO31="A",0,VLOOKUP(AP31,'Transmutation Table'!$A$2:$B$32,2)) -> 70 | AR31: =AQ31*$AR$13 -> 4.6666667 | AS31: =SUM(AJ31,AN31,AR31) -> 14 | AT31: =AVERAGE(AH31,AL31,AP31) -> 0 | AU31: =AVERAGE(AI31,AM31,AQ31) -> 70 | AV31: =SUM(S31,AF31,AS31) -> 26 | AY31: =SUM(AW31:AX31) -> 0 | AZ31: =50+(AY31/$AY$13)*50 -> 50 | BA31: =AZ31*$BA$13 -> 2.5 | BC31: =IFERROR(BB31/$T$13*100,0) -> 0 | BD31: =IF(BB31="A",0,VLOOKUP(BC31,'Transmutation Table'!$A$2:$B$32,2)) -> 70 | BE31: =BD31*$BE$13 -> 2.3333333 | BG31: =IFERROR(BF31/$X$13*100,0) -> 0 | BH31: =IF(BF31="A",0,VLOOKUP(BG31,'Transmutation Table'!$A$2:$B$32,2)) -> 70 | BI31: =BH31*$BI$13 -> 2.3333333 | BK31: =IFERROR(BJ31/#REF!*100,0) -> 0 | BL31: =IF(BJ31="A",0,VLOOKUP(BK31,'Transmutation Table'!$A$2:$B$32,2)) -> 70 | BM31: =BL31*$BM$13 -> 2.3333333 | BN31: =SUM(BE31,BI31,BM31) -> 7 | BO31: =AVERAGE(AY31) -> 0 | BP31: =AZ31 -> 50 | BQ31: =SUM(BA31,BN31) -> 9.5 | BR31: =SUM(G31,AV31,BQ31) -> 70.5 | BS31: =IFERROR(VLOOKUP(BR31,'Transmutation Table'!$B$2:$V$32,2),5) -> 5 | BT31: =IF(BR31>=75,"PASSED","FAILED") -> FAILED
A32: 19 | B32: Student 19 | E32: =_xlfn.CONCAT("/","",$F$12,"","") -> /10 | F32: =IFERROR(VLOOKUP((D32/$F$12)*100,'Transmutation Table'!$A$2:$B$32,2),0) -> 70 | G32: =$G$12*F32 -> 35 | O32: =COUNTIF(H32:N32,"P")+COUNTIF(H32:N32,"E")+COUNTIF(H32:N32,"L")*(1/3) -> 0 | P32: =COUNTA(H32:N32) -> 0 | Q32: =(P32-O32)*$Q$12 -> 0 | R32: =100-(Q32*$P$13) -> 100 | S32: =R32*$S$13 -> 5 | U32: =IFERROR(T32/$T$13*100,0) -> 0 | V32: =IF(T32="A",0,VLOOKUP(U32,'Transmutation Table'!$A$2:$B$32,2)) -> 70 | W32: =V32*$W$13 -> 2.3333333 | Y32: =IFERROR(X32/$X$13*100,0) -> 0 | Z32: =IF(X32="A",0,VLOOKUP(Y32,'Transmutation Table'!$A$2:$B$32,2)) -> 70 | AA32: =Z32*$AA$13 -> 2.3333333 | AC32: =IFERROR(AB32/$AB$13*100,0) -> 0 | AD32: =IF(AB32="A",0,VLOOKUP(AC32,'Transmutation Table'!$A$2:$B$32,2)) -> 70 | AE32: =AD32*$AE$13 -> 2.3333333 | AF32: =SUM(W32,AA32,AE32) -> 7 | AH32: =IFERROR(AG32/$AG$13*100,0) -> 0 | AI32: =IF(AG32="A",0,VLOOKUP(AH32,'Transmutation Table'!$A$2:$B$32,2)) -> 70 | AJ32: =AI32*$AJ$13 -> 4.6666667 | AL32: =IFERROR(AK32/$AK$13*100,0) -> 0 | AM32: =IF(AK32="A",0,VLOOKUP(AL32,'Transmutation Table'!$A$2:$B$32,2)) -> 70 | AN32: =AM32*$AN$13 -> 4.6666667 | AP32: =IFERROR(AO32/$AO$13*100,0) -> 0 | AQ32: =IF(AO32="A",0,VLOOKUP(AP32,'Transmutation Table'!$A$2:$B$32,2)) -> 70 | AR32: =AQ32*$AR$13 -> 4.6666667 | AS32: =SUM(AJ32,AN32,AR32) -> 14 | AT32: =AVERAGE(AH32,AL32,AP32) -> 0 | AU32: =AVERAGE(AI32,AM32,AQ32) -> 70 | AV32: =SUM(S32,AF32,AS32) -> 26 | AY32: =SUM(AW32:AX32) -> 0 | AZ32: =50+(AY32/$AY$13)*50 -> 50 | BA32: =AZ32*$BA$13 -> 2.5 | BC32: =IFERROR(BB32/$T$13*100,0) -> 0 | BD32: =IF(BB32="A",0,VLOOKUP(BC32,'Transmutation Table'!$A$2:$B$32,2)) -> 70 | BE32: =BD32*$BE$13 -> 2.3333333 | BG32: =IFERROR(BF32/$X$13*100,0) -> 0 | BH32: =IF(BF32="A",0,VLOOKUP(BG32,'Transmutation Table'!$A$2:$B$32,2)) -> 70 | BI32: =BH32*$BI$13 -> 2.3333333 | BK32: =IFERROR(BJ32/#REF!*100,0) -> 0 | BL32: =IF(BJ32="A",0,VLOOKUP(BK32,'Transmutation Table'!$A$2:$B$32,2)) -> 70 | BM32: =BL32*$BM$13 -> 2.3333333 | BN32: =SUM(BE32,BI32,BM32) -> 7 | BO32: =AVERAGE(AY32) -> 0 | BP32: =AZ32 -> 50 | BQ32: =SUM(BA32,BN32) -> 9.5 | BR32: =SUM(G32,AV32,BQ32) -> 70.5 | BS32: =IFERROR(VLOOKUP(BR32,'Transmutation Table'!$B$2:$V$32,2),5) -> 5 | BT32: =IF(BR32>=75,"PASSED","FAILED") -> FAILED
A33: 20 | B33: Student 20 | E33: =_xlfn.CONCAT("/","",$F$12,"","") -> /10 | F33: =IFERROR(VLOOKUP((D33/$F$12)*100,'Transmutation Table'!$A$2:$B$32,2),0) -> 70 | G33: =$G$12*F33 -> 35 | O33: =COUNTIF(H33:N33,"P")+COUNTIF(H33:N33,"E")+COUNTIF(H33:N33,"L")*(1/3) -> 0 | P33: =COUNTA(H33:N33) -> 0 | Q33: =(P33-O33)*$Q$12 -> 0 | R33: =100-(Q33*$P$13) -> 100 | S33: =R33*$S$13 -> 5 | U33: =IFERROR(T33/$T$13*100,0) -> 0 | V33: =IF(T33="A",0,VLOOKUP(U33,'Transmutation Table'!$A$2:$B$32,2)) -> 70 | W33: =V33*$W$13 -> 2.3333333 | Y33: =IFERROR(X33/$X$13*100,0) -> 0 | Z33: =IF(X33="A",0,VLOOKUP(Y33,'Transmutation Table'!$A$2:$B$32,2)) -> 70 | AA33: =Z33*$AA$13 -> 2.3333333 | AC33: =IFERROR(AB33/$AB$13*100,0) -> 0 | AD33: =IF(AB33="A",0,VLOOKUP(AC33,'Transmutation Table'!$A$2:$B$32,2)) -> 70 | AE33: =AD33*$AE$13 -> 2.3333333 | AF33: =SUM(W33,AA33,AE33) -> 7 | AH33: =IFERROR(AG33/$AG$13*100,0) -> 0 | AI33: =IF(AG33="A",0,VLOOKUP(AH33,'Transmutation Table'!$A$2:$B$32,2)) -> 70 | AJ33: =AI33*$AJ$13 -> 4.6666667 | AL33: =IFERROR(AK33/$AK$13*100,0) -> 0 | AM33: =IF(AK33="A",0,VLOOKUP(AL33,'Transmutation Table'!$A$2:$B$32,2)) -> 70 | AN33: =AM33*$AN$13 -> 4.6666667 | AP33: =IFERROR(AO33/$AO$13*100,0) -> 0 | AQ33: =IF(AO33="A",0,VLOOKUP(AP33,'Transmutation Table'!$A$2:$B$32,2)) -> 70 | AR33: =AQ33*$AR$13 -> 4.6666667 | AS33: =SUM(AJ33,AN33,AR33) -> 14 | AT33: =AVERAGE(AH33,AL33,AP33) -> 0 | AU33: =AVERAGE(AI33,AM33,AQ33) -> 70 | AV33: =SUM(S33,AF33,AS33) -> 26 | AY33: =SUM(AW33:AX33) -> 0 | AZ33: =50+(AY33/$AY$13)*50 -> 50 | BA33: =AZ33*$BA$13 -> 2.5 | BC33: =IFERROR(BB33/$T$13*100,0) -> 0 | BD33: =IF(BB33="A",0,VLOOKUP(BC33,'Transmutation Table'!$A$2:$B$32,2)) -> 70 | BE33: =BD33*$BE$13 -> 2.3333333 | BG33: =IFERROR(BF33/$X$13*100,0) -> 0 | BH33: =IF(BF33="A",0,VLOOKUP(BG33,'Transmutation Table'!$A$2:$B$32,2)) -> 70 | BI33: =BH33*$BI$13 -> 2.3333333 | BK33: =IFERROR(BJ33/#REF!*100,0) -> 0 | BL33: =IF(BJ33="A",0,VLOOKUP(BK33,'Transmutation Table'!$A$2:$B$32,2)) -> 70 | BM33: =BL33*$BM$13 -> 2.3333333 | BN33: =SUM(BE33,BI33,BM33) -> 7 | BO33: =AVERAGE(AY33) -> 0 | BP33: =AZ33 -> 50 | BQ33: =SUM(BA33,BN33) -> 9.5 | BR33: =SUM(G33,AV33,BQ33) -> 70.5 | BS33: =IFERROR(VLOOKUP(BR33,'Transmutation Table'!$B$2:$V$32,2),5) -> 5 | BT33: =IF(BR33>=75,"PASSED","FAILED") -> FAILED
... A38: 25 | B38: Student 25 | E38: =_xlfn.CONCAT("/","",$F$12,"","") -> /10 | F38: =IFERROR(VLOOKUP((D38/$F$12)*100,'Transmutation Table'!$A$2:$B$32,2),0) -> 70 | G38: =$G$12*F38 -> 35 | O38: =COUNTIF(H38:N38,"P")+COUNTIF(H38:N38,"E")+COUNTIF(H38:N38,"L")*(1/3) -> 0 | P38: =COUNTA(H38:N38) -> 0 | Q38: =(P38-O38)*$Q$12 -> 0 | R38: =100-(Q38*$P$13) -> 100 | S38: =R38*$S$13 -> 5 | U38: =IFERROR(T38/$T$13*100,0) -> 0 | V38: =IF(T38="A",0,VLOOKUP(U38,'Transmutation Table'!$A$2:$B$32,2)) -> 70 | W38: =V38*$W$13 -> 2.3333333 | Y38: =IFERROR(X38/$X$13*100,0) -> 0 | Z38: =IF(X38="A",0,VLOOKUP(Y38,'Transmutation Table'!$A$2:$B$32,2)) -> 70 | AA38: =Z38*$AA$13 -> 2.3333333 | AC38: =IFERROR(AB38/$AB$13*100,0) -> 0 | AD38: =IF(AB38="A",0,VLOOKUP(AC38,'Transmutation Table'!$A$2:$B$32,2)) -> 70 | AE38: =AD38*$AE$13 -> 2.3333333 | AF38: =SUM(W38,AA38,AE38) -> 7 | AH38: =IFERROR(AG38/$AG$13*100,0) -> 0 | AI38: =IF(AG38="A",0,VLOOKUP(AH38,'Transmutation Table'!$A$2:$B$32,2)) -> 70 | AJ38: =AI38*$AJ$13 -> 4.6666667 | AL38: =IFERROR(AK38/$AK$13*100,0) -> 0 | AM38: =IF(AK38="A",0,VLOOKUP(AL38,'Transmutation Table'!$A$2:$B$32,2)) -> 70 | AN38: =AM38*$AN$13 -> 4.6666667 | AP38: =IFERROR(AO38/$AO$13*100,0) -> 0 | AQ38: =IF(AO38="A",0,VLOOKUP(AP38,'Transmutation Table'!$A$2:$B$32,2)) -> 70 | AR38: =AQ38*$AR$13 -> 4.6666667 | AS38: =SUM(AJ38,AN38,AR38) -> 14 | AT38: =AVERAGE(AH38,AL38,AP38) -> 0 | AU38: =AVERAGE(AI38,AM38,AQ38) -> 70 | AV38: =SUM(S38,AF38,AS38) -> 26 | AY38: =SUM(AW38:AX38) -> 0 | AZ38: =50+(AY38/$AY$13)*50 -> 50 | BA38: =AZ38*$BA$13 -> 2.5 | BC38: =IFERROR(BB38/$T$13*100,0) -> 0 | BD38: =IF(BB38="A",0,VLOOKUP(BC38,'Transmutation Table'!$A$2:$B$32,2)) -> 70 | BE38: =BD38*$BE$13 -> 2.3333333 | BG38: =IFERROR(BF38/$X$13*100,0) -> 0 | BH38: =IF(BF38="A",0,VLOOKUP(BG38,'Transmutation Table'!$A$2:$B$32,2)) -> 70 | BI38: =BH38*$BI$13 -> 2.3333333 | BK38: =IFERROR(BJ38/#REF!*100,0) -> 0 | BL38: =IF(BJ38="A",0,VLOOKUP(BK38,'Transmutation Table'!$A$2:$B$32,2)) -> 70 | BM38: =BL38*$BM$13 -> 2.3333333 | BN38: =SUM(BE38,BI38,BM38) -> 7 | BO38: =AVERAGE(AY38) -> 0 | BP38: =AZ38 -> 50 | BQ38: =SUM(BA38,BN38) -> 9.5 | BR38: =SUM(G38,AV38,BQ38) -> 70.5 | BS38: =IFERROR(VLOOKUP(BR38,'Transmutation Table'!$B$2:$V$32,2),5) -> 5 | BT38: =IF(BR38>=75,"PASSED","FAILED") -> FAILED
A39: 26 | B39: Student 26 | E39: =_xlfn.CONCAT("/","",$F$12,"","") -> /10 | F39: =IFERROR(VLOOKUP((D39/$F$12)*100,'Transmutation Table'!$A$2:$B$32,2),0) -> 70 | G39: =$G$12*F39 -> 35 | O39: =COUNTIF(H39:N39,"P")+COUNTIF(H39:N39,"E")+COUNTIF(H39:N39,"L")*(1/3) -> 0 | P39: =COUNTA(H39:N39) -> 0 | Q39: =(P39-O39)*$Q$12 -> 0 | R39: =100-(Q39*$P$13) -> 100 | S39: =R39*$S$13 -> 5 | U39: =IFERROR(T39/$T$13*100,0) -> 0 | V39: =IF(T39="A",0,VLOOKUP(U39,'Transmutation Table'!$A$2:$B$32,2)) -> 70 | W39: =V39*$W$13 -> 2.3333333 | Y39: =IFERROR(X39/$X$13*100,0) -> 0 | Z39: =IF(X39="A",0,VLOOKUP(Y39,'Transmutation Table'!$A$2:$B$32,2)) -> 70 | AA39: =Z39*$AA$13 -> 2.3333333 | AC39: =IFERROR(AB39/$AB$13*100,0) -> 0 | AD39: =IF(AB39="A",0,VLOOKUP(AC39,'Transmutation Table'!$A$2:$B$32,2)) -> 70 | AE39: =AD39*$AE$13 -> 2.3333333 | AF39: =SUM(W39,AA39,AE39) -> 7 | AH39: =IFERROR(AG39/$AG$13*100,0) -> 0 | AI39: =IF(AG39="A",0,VLOOKUP(AH39,'Transmutation Table'!$A$2:$B$32,2)) -> 70 | AJ39: =AI39*$AJ$13 -> 4.6666667 | AL39: =IFERROR(AK39/$AK$13*100,0) -> 0 | AM39: =IF(AK39="A",0,VLOOKUP(AL39,'Transmutation Table'!$A$2:$B$32,2)) -> 70 | AN39: =AM39*$AN$13 -> 4.6666667 | AP39: =IFERROR(AO39/$AO$13*100,0) -> 0 | AQ39: =IF(AO39="A",0,VLOOKUP(AP39,'Transmutation Table'!$A$2:$B$32,2)) -> 70 | AR39: =AQ39*$AR$13 -> 4.6666667 | AS39: =SUM(AJ39,AN39,AR39) -> 14 | AT39: =AVERAGE(AH39,AL39,AP39) -> 0 | AU39: =AVERAGE(AI39,AM39,AQ39) -> 70 | AV39: =SUM(S39,AF39,AS39) -> 26 | AY39: =SUM(AW39:AX39) -> 0 | AZ39: =50+(AY39/$AY$13)*50 -> 50 | BA39: =AZ39*$BA$13 -> 2.5 | BC39: =IFERROR(BB39/$T$13*100,0) -> 0 | BD39: =IF(BB39="A",0,VLOOKUP(BC39,'Transmutation Table'!$A$2:$B$32,2)) -> 70 | BE39: =BD39*$BE$13 -> 2.3333333 | BG39: =IFERROR(BF39/$X$13*100,0) -> 0 | BH39: =IF(BF39="A",0,VLOOKUP(BG39,'Transmutation Table'!$A$2:$B$32,2)) -> 70 | BI39: =BH39*$BI$13 -> 2.3333333 | BK39: =IFERROR(BJ39/#REF!*100,0) -> 0 | BL39: =IF(BJ39="A",0,VLOOKUP(BK39,'Transmutation Table'!$A$2:$B$32,2)) -> 70 | BM39: =BL39*$BM$13 -> 2.3333333 | BN39: =SUM(BE39,BI39,BM39) -> 7 | BO39: =AVERAGE(AY39) -> 0 | BP39: =AZ39 -> 50 | BQ39: =SUM(BA39,BN39) -> 9.5 | BR39: =SUM(G39,AV39,BQ39) -> 70.5 | BS39: =IFERROR(VLOOKUP(BR39,'Transmutation Table'!$B$2:$V$32,2),5) -> 5 | BT39: =IF(BR39>=75,"PASSED","FAILED") -> FAILED | BV39: Permit
A40: 27 | B40: Student 27 | E40: =_xlfn.CONCAT("/","",$F$12,"","") -> /10 | F40: =IFERROR(VLOOKUP((D40/$F$12)*100,'Transmutation Table'!$A$2:$B$32,2),0) -> 70 | G40: =$G$12*F40 -> 35 | O40: =COUNTIF(H40:N40,"P")+COUNTIF(H40:N40,"E")+COUNTIF(H40:N40,"L")*(1/3) -> 0 | P40: =COUNTA(H40:N40) -> 0 | Q40: =(P40-O40)*$Q$12 -> 0 | R40: =100-(Q40*$P$13) -> 100 | S40: =R40*$S$13 -> 5 | U40: =IFERROR(T40/$T$13*100,0) -> 0 | V40: =IF(T40="A",0,VLOOKUP(U40,'Transmutation Table'!$A$2:$B$32,2)) -> 70 | W40: =V40*$W$13 -> 2.3333333 | Y40: =IFERROR(X40/$X$13*100,0) -> 0 | Z40: =IF(X40="A",0,VLOOKUP(Y40,'Transmutation Table'!$A$2:$B$32,2)) -> 70 | AA40: =Z40*$AA$13 -> 2.3333333 | AC40: =IFERROR(AB40/$AB$13*100,0) -> 0 | AD40: =IF(AB40="A",0,VLOOKUP(AC40,'Transmutation Table'!$A$2:$B$32,2)) -> 70 | AE40: =AD40*$AE$13 -> 2.3333333 | AF40: =SUM(W40,AA40,AE40) -> 7 | AH40: =IFERROR(AG40/$AG$13*100,0) -> 0 | AI40: =IF(AG40="A",0,VLOOKUP(AH40,'Transmutation Table'!$A$2:$B$32,2)) -> 70 | AJ40: =AI40*$AJ$13 -> 4.6666667 | AL40: =IFERROR(AK40/$AK$13*100,0) -> 0 | AM40: =IF(AK40="A",0,VLOOKUP(AL40,'Transmutation Table'!$A$2:$B$32,2)) -> 70 | AN40: =AM40*$AN$13 -> 4.6666667 | AP40: =IFERROR(AO40/$AO$13*100,0) -> 0 | AQ40: =IF(AO40="A",0,VLOOKUP(AP40,'Transmutation Table'!$A$2:$B$32,2)) -> 70 | AR40: =AQ40*$AR$13 -> 4.6666667 | AS40: =SUM(AJ40,AN40,AR40) -> 14 | AT40: =AVERAGE(AH40,AL40,AP40) -> 0 | AU40: =AVERAGE(AI40,AM40,AQ40) -> 70 | AV40: =SUM(S40,AF40,AS40) -> 26 | AY40: =SUM(AW40:AX40) -> 0 | AZ40: =50+(AY40/$AY$13)*50 -> 50 | BA40: =AZ40*$BA$13 -> 2.5 | BC40: =IFERROR(BB40/$T$13*100,0) -> 0 | BD40: =IF(BB40="A",0,VLOOKUP(BC40,'Transmutation Table'!$A$2:$B$32,2)) -> 70 | BE40: =BD40*$BE$13 -> 2.3333333 | BG40: =IFERROR(BF40/$X$13*100,0) -> 0 | BH40: =IF(BF40="A",0,VLOOKUP(BG40,'Transmutation Table'!$A$2:$B$32,2)) -> 70 | BI40: =BH40*$BI$13 -> 2.3333333 | BK40: =IFERROR(BJ40/#REF!*100,0) -> 0 | BL40: =IF(BJ40="A",0,VLOOKUP(BK40,'Transmutation Table'!$A$2:$B$32,2)) -> 70 | BM40: =BL40*$BM$13 -> 2.3333333 | BN40: =SUM(BE40,BI40,BM40) -> 7 | BO40: =AVERAGE(AY40) -> 0 | BP40: =AZ40 -> 50 | BQ40: =SUM(BA40,BN40) -> 9.5 | BR40: =SUM(G40,AV40,BQ40) -> 70.5 | BS40: =IFERROR(VLOOKUP(BR40,'Transmutation Table'!$B$2:$V$32,2),5) -> 5 | BT40: =IF(BR40>=75,"PASSED","FAILED") -> FAILED
A41: 28 | B41: Student 28 | E41: =_xlfn.CONCAT("/","",$F$12,"","") -> /10 | F41: =IFERROR(VLOOKUP((D41/$F$12)*100,'Transmutation Table'!$A$2:$B$32,2),0) -> 70 | G41: =$G$12*F41 -> 35 | O41: =COUNTIF(H41:N41,"P")+COUNTIF(H41:N41,"E")+COUNTIF(H41:N41,"L")*(1/3) -> 0 | P41: =COUNTA(H41:N41) -> 0 | Q41: =(P41-O41)*$Q$12 -> 0 | R41: =100-(Q41*$P$13) -> 100 | S41: =R41*$S$13 -> 5 | U41: =IFERROR(T41/$T$13*100,0) -> 0 | V41: =IF(T41="A",0,VLOOKUP(U41,'Transmutation Table'!$A$2:$B$32,2)) -> 70 | W41: =V41*$W$13 -> 2.3333333 | Y41: =IFERROR(X41/$X$13*100,0) -> 0 | Z41: =IF(X41="A",0,VLOOKUP(Y41,'Transmutation Table'!$A$2:$B$32,2)) -> 70 | AA41: =Z41*$AA$13 -> 2.3333333 | AC41: =IFERROR(AB41/$AB$13*100,0) -> 0 | AD41: =IF(AB41="A",0,VLOOKUP(AC41,'Transmutation Table'!$A$2:$B$32,2)) -> 70 | AE41: =AD41*$AE$13 -> 2.3333333 | AF41: =SUM(W41,AA41,AE41) -> 7 | AH41: =IFERROR(AG41/$AG$13*100,0) -> 0 | AI41: =IF(AG41="A",0,VLOOKUP(AH41,'Transmutation Table'!$A$2:$B$32,2)) -> 70 | AJ41: =AI41*$AJ$13 -> 4.6666667 | AL41: =IFERROR(AK41/$AK$13*100,0) -> 0 | AM41: =IF(AK41="A",0,VLOOKUP(AL41,'Transmutation Table'!$A$2:$B$32,2)) -> 70 | AN41: =AM41*$AN$13 -> 4.6666667 | AP41: =IFERROR(AO41/$AO$13*100,0) -> 0 | AQ41: =IF(AO41="A",0,VLOOKUP(AP41,'Transmutation Table'!$A$2:$B$32,2)) -> 70 | AR41: =AQ41*$AR$13 -> 4.6666667 | AS41: =SUM(AJ41,AN41,AR41) -> 14 | AT41: =AVERAGE(AH41,AL41,AP41) -> 0 | AU41: =AVERAGE(AI41,AM41,AQ41) -> 70 | AV41: =SUM(S41,AF41,AS41) -> 26 | AY41: =SUM(AW41:AX41) -> 0 | AZ41: =50+(AY41/$AY$13)*50 -> 50 | BA41: =AZ41*$BA$13 -> 2.5 | BC41: =IFERROR(BB41/$T$13*100,0) -> 0 | BD41: =IF(BB41="A",0,VLOOKUP(BC41,'Transmutation Table'!$A$2:$B$32,2)) -> 70 | BE41: =BD41*$BE$13 -> 2.3333333 | BG41: =IFERROR(BF41/$X$13*100,0) -> 0 | BH41: =IF(BF41="A",0,VLOOKUP(BG41,'Transmutation Table'!$A$2:$B$32,2)) -> 70 | BI41: =BH41*$BI$13 -> 2.3333333 | BK41: =IFERROR(BJ41/#REF!*100,0) -> 0 | BL41: =IF(BJ41="A",0,VLOOKUP(BK41,'Transmutation Table'!$A$2:$B$32,2)) -> 70 | BM41: =BL41*$BM$13 -> 2.3333333 | BN41: =SUM(BE41,BI41,BM41) -> 7 | BO41: =AVERAGE(AY41) -> 0 | BP41: =AZ41 -> 50 | BQ41: =SUM(BA41,BN41) -> 9.5 | BR41: =SUM(G41,AV41,BQ41) -> 70.5 | BS41: =IFERROR(VLOOKUP(BR41,'Transmutation Table'!$B$2:$V$32,2),5) -> 5 | BT41: =IF(BR41>=75,"PASSED","FAILED") -> FAILED
